<?xml version="1.0"?>
<robot xmlns:xacro="http://www.ros.org/wiki/xacro" name="hans_bot">

  
  <xacro:include filename="$(find velodyne_description)/urdf/VLP-16.urdf.xacro"/>
  <xacro:VLP-16 parent="cam" name="velodyne" topic="/velodyne_points" hz="10.0" samples="440.0" gpu="false">
     <origin xyz="0 0 0.2" rpy="0 0 0" />
  </xacro:VLP-16>


  <link name="base_link">
    <visual>
      <origin xyz="0 0 0" rpy="0 0 0"/>
      <geometry>
        <box size="0.35 0.4 0.10"/>
      </geometry>
      <material name="acrylic">
        <color rgba="1 1 1 0.8"/>
      </material>
    </visual>
    <collision>
      <origin xyz="0 0 0" rpy="0 0 0"/>
      <geometry>
        <box size="0.35 0.4 0.10"/>
      </geometry>
    </collision>
    <inertial>
      <mass value="200.0"/>
      <inertia ixx="10.0" ixy="0.0" ixz="0.0" iyy="10.0" iyz="0.0" izz="10.0"/>
    </inertial>
  </link>

  <joint name="cam_stand_joint" type="fixed">
    <origin xyz="0.0 0.0 0.45" rpy="0 0 0" />
    <parent link="base_link"/>
    <child link="cam_stand" />
  </joint>

  <!-- the model -->
  <link name="cam_stand">
    <inertial>
      <mass value="1" />
      <origin xyz="0 0 0.00" />
      <inertia ixx="1.0" ixy="0.0" ixz="0.0"
        iyy="1.0" iyz="0.0"
        izz="1.0" />
    </inertial>
    <visual>
      <geometry>
        <box size=".1 .1 .9" /> <!-- does not need to match collision -->
      </geometry>
    </visual>
    <collision>
      <origin xyz="0 0 0" rpy="0 0 0"/>
      <geometry>
        <box size="0.6 0.4 0.10"/>
      </geometry>
    </collision>
  </link>


 

   <joint name="cam_prismatic" type="prismatic">
      <child link="cam_stand_primsatic" />
      <parent link="cam_stand"/>
      <origin xyz="0.0 0 0.475" rpy="0 0 0"/>
      <axis xyz="0 0 -1"/>
      <limit effort="1000.0" lower="-0.2" upper="0.2" velocity="0.5"/>
    </joint>

 

  <transmission name="cam_prismatic_trans">
    <type>transmission_interface/SimpleTransmission</type>
    <joint name="cam_prismatic">
      <hardwareInterface>hardware_interface/EffortJointInterface</hardwareInterface>
    </joint>
    <actuator name="motorToCamPris">
      <hardwareInterface>hardware_interface/EffortJointInterface</hardwareInterface>
      <mechanicalReduction>1</mechanicalReduction>
    </actuator>
  </transmission>


  <link name="cam_stand_primsatic">
    <inertial>
      <mass value=".1" />
      <origin xyz="0 0 0.00" />
      <inertia ixx="1.0" ixy="0.0" ixz="0.0"
        iyy="1.0" iyz="0.0"
        izz="1.0" />
    </inertial>
    <visual>
      <geometry>
        <box size="0.01 0.01 0.01" /> <!-- does not need to match collision -->
      </geometry>
    </visual>
  </link>
 

   <joint name="cam_revolute" type="continuous">
      <origin xyz="0.0 0.0 0.0" rpy="0 0 0"/>
      <axis rpy="0 0 0" xyz="0 1 0"/>
      <parent link="cam_stand_primsatic"/>
      <child link="cam"/>
    </joint>

     
  <transmission name="cam_revolute_trans">
    <type>transmission_interface/SimpleTransmission</type>
    <joint name="cam_revolute">
      <hardwareInterface>hardware_interface/EffortJointInterface</hardwareInterface>
    </joint>
    <actuator name="motorToCamRev">
      <hardwareInterface>hardware_interface/EffortJointInterface</hardwareInterface>
      <mechanicalReduction>1</mechanicalReduction>
    </actuator>
  </transmission>



  <link name="cam">
    <inertial>
      <mass value=".1" />
      <origin xyz="0 0.0 0.00" />
      <inertia ixx="1.0" ixy="0.0" ixz="0.0"
        iyy="1.0" iyz="0.0"
        izz="1.0" />
    </inertial>
    <visual>
      <geometry>
        <box size="0.15 0.15 0.15" /> <!-- does not need to match collision -->
      </geometry>
    </visual>
  </link>

  <!-- <gazebo>
    <plugin name="imu_plugin" filename="libgazebo_ros_imu.so">
      <alwaysOn>true</alwaysOn>
      <bodyName>imu_link</bodyName>
      <topicName>imu</topicName>
      <serviceName>imu_service</serviceName>
      <gaussianNoise>0.0</gaussianNoise>
      <updateRate>250.0</updateRate>
      <rateDrift>0. 0. 0.</rateDrift>
      <accelDrift>0. 0. 0.</accelDrift>
    </plugin>
  </gazebo> -->




  <gazebo reference="cam">
    <gravity>true</gravity>
    <sensor name="imu_sensor" type="imu">
      <always_on>true</always_on>
      <update_rate>10</update_rate>
      <visualize>true</visualize>
      <topic>imu</topic>
      <plugin filename="libgazebo_ros_imu_sensor.so" name="imu_plugin">
        <topicName>imu</topicName>
        <bodyName>cam</bodyName>
        <updateRateHZ>10</updateRateHZ>
        <gaussianNoise>0.1</gaussianNoise>
        <xyzOffset>0 0 0</xyzOffset>
        <rpyOffset>0 0 0</rpyOffset>
        <frameName>cam</frameName>
        <initialOrientationAsReference>false</initialOrientationAsReference>
      </plugin>
      <pose>0 0 0 0 0 0</pose>
    </sensor>
  </gazebo>


  <link name="wh_left_back">
    <visual>
      <origin xyz="0 0 0" rpy="1.57079632679 0 0"/>
      <geometry>
        <cylinder length="0.04" radius="0.2"/>
      </geometry>
    </visual>
    <collision>
      <origin xyz="0 0 0" rpy="1.57079632679 0 0"/>
      <geometry>
        <cylinder length="0.04" radius="0.2"/>
      </geometry>
    </collision>
    <inertial>
      <mass value="1.0"/>
      <inertia ixx="1.0" ixy="0.0" ixz="0.0" iyy="1.0" iyz="0.0" izz="1.0"/>
    </inertial>
  </link>

  <joint name="base_link_wh_left_back" type="continuous">
    <origin xyz="-.25 .25 0" rpy="0 0 0"/>
    <axis rpy="0 0 0" xyz="0 1 0"/>
    <parent link="base_link"/>
    <child link="wh_left_back"/>
  </joint>

  <transmission name="base_link_wh_left_back_wheel_trans">
    <type>transmission_interface/SimpleTransmission</type>
    <actuator name="base_link_wh_left_back_wheel_motor">
      <mechanicalReduction>1</mechanicalReduction>
    </actuator>
    <joint name="base_link_wh_left_back">
      <hardwareInterface>hardware_interface/VelocityJointInterface</hardwareInterface>
    </joint>
  </transmission>


  <link name="wh_right_back">
    <visual>
      <origin xyz="0 0 0" rpy="1.57079632679 0 0"/>
      <geometry>
        <cylinder length="0.04" radius="0.2"/>
      </geometry>
    </visual>
    <collision>
      <origin xyz="0 0 0" rpy="1.57079632679 0 0"/>
      <geometry>
        <cylinder length="0.04" radius="0.2"/>
      </geometry>
    </collision>
    <inertial>
      <mass value="1.0"/>
      <inertia ixx="1.0" ixy="0.0" ixz="0.0" iyy="1.0" iyz="0.0" izz="1.0"/>
    </inertial>
  </link>

  <joint name="base_link_wh_right_back" type="continuous">
    <origin xyz="-.25 -.25 0" rpy="0 0 0"/>
    <axis rpy="0 0 0" xyz="0 1 0"/>
    <parent link="base_link"/>
    <child link="wh_right_back"/>
  </joint>

  <transmission name="base_link_wh_right_back_wheel_trans">
    <type>transmission_interface/SimpleTransmission</type>
    <actuator name="base_link_wh_right_back_wheel_motor">
      <mechanicalReduction>1</mechanicalReduction>
    </actuator>
    <joint name="base_link_wh_right_back">
      <hardwareInterface>hardware_interface/VelocityJointInterface</hardwareInterface>
    </joint>
  </transmission>


  <link name="wh_left_front">
    <visual>
      <origin xyz="0 0 0" rpy="1.57079632679 0 0"/>
      <geometry>
        <cylinder length="0.04" radius="0.2"/>
      </geometry>
    </visual>
    <collision>
      <origin xyz="0 0 0" rpy="1.57079632679 0 0"/>
      <geometry>
        <cylinder length="0.04" radius="0.2"/>
      </geometry>
    </collision>
    <inertial>
      <mass value="1.0"/>
      <inertia ixx="1.0" ixy="0.0" ixz="0.0" iyy="1.0" iyz="0.0" izz="1.0"/>
    </inertial>
  </link>

  <joint name="base_link_wh_left_front" type="continuous">
    <origin xyz="0.25 0.25 0" rpy="0 0 0"/>
    <axis rpy="0 0 0" xyz="0 1 0"/>
    <parent link="base_link"/>
    <child link="wh_left_front"/>
  </joint>

  <transmission name="base_link_wh_left_front_wheel_trans">
    <type>transmission_interface/SimpleTransmission</type>
    <actuator name="base_link_wh_left_front_wheel_motor">
      <mechanicalReduction>1</mechanicalReduction>
    </actuator>
    <joint name="base_link_wh_left_front">
      <hardwareInterface>hardware_interface/VelocityJointInterface</hardwareInterface>
    </joint>
  </transmission>


  <link name="wh_right_front">
    <visual>
      <origin xyz="0 0 0" rpy="1.57079632679 0 0"/>
      <geometry>
        <cylinder length="0.04" radius="0.2"/>
      </geometry>
    </visual>
    <collision>
      <origin xyz="0 0 0" rpy="1.57079632679 0 0"/>
      <geometry>
        <cylinder length="0.04" radius="0.2"/>
      </geometry>
    </collision>
    <inertial>
      <mass value="1.0"/>
      <inertia ixx="1.0" ixy="0.0" ixz="0.0" iyy="1.0" iyz="0.0" izz="1.0"/>
    </inertial>
  </link>

  <joint name="base_link_wh_right_front" type="continuous">
    <origin xyz="0.25 -.25 0" rpy="0 0 0"/>
    <axis rpy="0 0 0" xyz="0 1 0"/>
    <parent link="base_link"/>
    <child link="wh_right_front"/>
  </joint>

  <transmission name="base_link_wh_right_front_wheel_trans">
    <type>transmission_interface/SimpleTransmission</type>
    <actuator name="base_link_wh_right_front_wheel_motor">
      <mechanicalReduction>1</mechanicalReduction>
    </actuator>
    <joint name="base_link_wh_right_front">
      <hardwareInterface>hardware_interface/VelocityJointInterface</hardwareInterface>
    </joint>
  </transmission>





    

  

  


  <!-- =================== Gazebo ==================== -->
  <gazebo>
    <plugin name="gazebo_ros_control" filename="libgazebo_ros_control.so">
      <robotNamespace>/</robotNamespace>
    </plugin>
  </gazebo>
</robot>