<?xml version="1.0" encoding="utf-8"?>
<!-- =================================================================================== -->
<!-- |    This document was autogenerated by xacro from mid40_atom.xacro               | -->
<!-- |    EDITING THIS FILE BY HAND IS NOT RECOMMENDED                                 | -->
<!-- =================================================================================== -->
<robot name="atom">
  <!-- Make Chassis of Bot -->
  <link name="chassis">
    <pose>0 0 0.1 0 0 0</pose>
    <inertial>
      <mass value="15"/>
      <origin rpy=" 0 0 0" xyz="0.0 0 0"/>
      <inertia ixx="0.147116667" ixy="0" ixz="0" iyy="0.334951167" iyz="0" izz="0.3978345"/>
    </inertial>
    <collision name="collision">
      <origin rpy=" 0 0 0" xyz="0 0 0.05"/>
      <geometry>
        <box size="0.5 0.5 0.2"/>
      </geometry>
    </collision>
    <visual name="chassis_visual">
      <origin rpy=" 0 0 0" xyz="0 0 0.05"/>
      <geometry>
        <box size="0.5 0.5 0.2"/>
      </geometry>
    </visual>
  </link>
  <!-- Right Wheel Back -->
  <link name="right_wheel_back">
    <inertial>
      <mass value="5"/>
      <origin rpy="0 1.5707 1.5707" xyz="0 0 0"/>
      <inertia ixx="0.1" ixy="0.0" ixz="0.0" iyy="0.1" iyz="0.0" izz="0.1"/>
    </inertial>
    <visual>
      <origin rpy="0 1.5707 1.5707" xyz="0 0 0"/>
      <geometry>
        <cylinder length="0.05" radius="0.1"/>
      </geometry>
    </visual>
    <collision>
      <origin rpy="0 1.5707 1.5707" xyz="0 0 0"/>
      <geometry>
        <cylinder length="0.05" radius="0.1"/>
      </geometry>
    </collision>
  </link>
  <!-- Right Wheel Front-->
  <link name="right_wheel_front">
    <inertial>
      <mass value="5"/>
      <origin rpy="0 1.5707 1.5707" xyz="0 0 0"/>
      <inertia ixx="0.1" ixy="0.0" ixz="0.0" iyy="0.1" iyz="0.0" izz="0.1"/>
    </inertial>
    <visual>
      <origin rpy="0 1.5707 1.5707" xyz="0 0 0"/>
      <geometry>
        <cylinder length="0.05" radius="0.1"/>
      </geometry>
    </visual>
    <collision>
      <origin rpy="0 1.5707 1.5707" xyz="0 0 0"/>
      <geometry>
        <cylinder length="0.05" radius="0.1"/>
      </geometry>
    </collision>
  </link>
  <!-- Left wheel Back-->
  <link name="left_wheel_back">
    <inertial>
      <mass value="5"/>
      <origin rpy="0 1.5707 1.5707" xyz="0 0 0"/>
      <inertia ixx="0.1" ixy="0.0" ixz="0.0" iyy="0.1" iyz="0.0" izz="0.1"/>
    </inertial>
    <visual>
      <origin rpy="0 1.5707 1.5707" xyz="0 0 0"/>
      <geometry>
        <cylinder length="0.05" radius="0.1"/>
      </geometry>
    </visual>
    <collision>
      <origin rpy="0 1.5707 1.5707" xyz="0 0 0"/>
      <geometry>
        <cylinder length="0.05" radius="0.1"/>
      </geometry>
    </collision>
  </link>
  <!-- Left wheel Front-->
  <link name="left_wheel_front">
    <inertial>
      <mass value="5"/>
      <origin rpy="0 1.5707 1.5707" xyz="0 0 0"/>
      <inertia ixx="0.1" ixy="0.0" ixz="0.0" iyy="0.1" iyz="0.0" izz="0.1"/>
    </inertial>
    <visual>
      <origin rpy="0 1.5707 1.5707" xyz="0 0 0"/>
      <geometry>
        <cylinder length="0.05" radius="0.1"/>
      </geometry>
    </visual>
    <collision>
      <origin rpy="0 1.5707 1.5707" xyz="0 0 0"/>
      <geometry>
        <cylinder length="0.05" radius="0.1"/>
      </geometry>
    </collision>
  </link>
  <!-- Camera -->
  <link name="camera">
    <inertial>
      <mass value="0.1"/>
      <origin rpy="0 0 0" xyz="0 0 0"/>
      <inertia ixx="1e-6" ixy="0.0" ixz="0.0" iyy="1e-6" iyz="0.0" izz="1e-6"/>
    </inertial>
    <visual>
      <origin rpy="0 0 0" xyz="0 0 0"/>
      <geometry>
        <box size="0.05 0.05 0.05"/>
      </geometry>
    </visual>
    <collision>
      <origin rpy="0 0 0" xyz="0 0 0"/>
      <geometry>
        <box size="0.05 0.05 0.05"/>
      </geometry>
    </collision>
  </link>
  <!-- livox mid40 Lidar -->
  <link name="Livox_Mid40">
    <inertial>
      <mass value="0.1"/>
      <inertia ixx="0.01" ixy="0" ixz="0" iyy="0.01" iyz="0" izz="0.01"/>
    </inertial>
    <visual>
      <origin rpy="0 0 0" xyz="0.00 0 0.00"/>
      <geometry>
        <mesh filename="package://livox_laser_simulation/meshes/livox_mid40.dae">
		  </mesh>
      </geometry>
    </visual>
    <collision>
      <origin rpy="0 0 0" xyz="0 0 0"/>
      <geometry>
        <mesh filename="package://livox_laser_simulation/meshes/livox_mid40.dae"> 
			  </mesh>
      </geometry>
    </collision>
  </link>
  <!-- Project center to the ground -->
  <link name="robot_footprint"/>
  <!-- Define Joints -->
  <!-- Right Wheel Joint Back-->
  <joint name="right_wheel_hinge_back" type="continuous">
    <origin rpy="0 0 0" xyz="-0.2 -0.30 0"/>
    <parent link="chassis"/>
    <child link="right_wheel_back"/>
    <axis rpy="0 0 0" xyz="0 1 0"/>
    <limit effort="10000" velocity="1000"/>
    <dynamics damping="1.0" friction="1.0"/>
  </joint>
  <!-- Right Wheel Joint Front-->
  <joint name="right_wheel_hinge_front" type="continuous">
    <origin rpy="0 0 0" xyz="0.2 -0.30 0"/>
    <parent link="chassis"/>
    <child link="right_wheel_front"/>
    <axis rpy="0 0 0" xyz="0 1 0"/>
    <limit effort="10000" velocity="1000"/>
    <dynamics damping="1.0" friction="1.0"/>
  </joint>
  <!-- Left Wheel Joint Back-->
  <joint name="left_wheel_hinge_back" type="continuous">
    <origin rpy="0 0 0" xyz="-0.2 0.30 0"/>
    <parent link="chassis"/>
    <child link="left_wheel_back"/>
    <axis rpy="0 0 0" xyz="0 1 0"/>
    <limit effort="10000" velocity="1000"/>
    <dynamics damping="1.0" friction="1.0"/>
  </joint>
  <!-- Left Wheel Joint Front-->
  <joint name="left_wheel_hinge_front" type="continuous">
    <origin rpy="0 0 0" xyz="0.2 0.30 0"/>
    <parent link="chassis"/>
    <child link="left_wheel_front"/>
    <axis rpy="0 0 0" xyz="0 1 0"/>
    <limit effort="10000" velocity="1000"/>
    <dynamics damping="1.0" friction="1.0"/>
  </joint>
  <!-- Camera Joint -->
  <joint name="camera_joint" type="fixed">
    <origin rpy="0 0 0" xyz="0.26 0 0"/>
    <parent link="chassis"/>
    <child link="camera"/>
    <axis xyz="0 1 0"/>
  </joint>
  <!-- livox mid40 Joint -->
  <joint name="livox_mid40_joint" type="fixed">
    <origin rpy="0 0 0" xyz="0.2 0 0.2"/>
    <parent link="chassis"/>
    <child link="Livox_Mid40"/>
    <axis xyz="0 1 0"/>
  </joint>
  <joint name="robot_footprint_joint" type="fixed">
    <origin rpy="0 0 0" xyz="0 0 0"/>
    <parent link="robot_footprint"/>
    <child link="chassis"/>
  </joint>
  <!-- Color of bot -->
  <gazebo reference="left_wheel_front">
    <material>Gazebo/Green</material>
    <kp>1000000.0</kp>
    <!-- kp and kd for rubber -->
    <kd>100.0</kd>
    <mu1>1.0</mu1>
    <mu2>1.0</mu2>
    <maxVel>1.0</maxVel>
    <minDepth>0.00</minDepth>
  </gazebo>
  <gazebo reference="left_wheel_back">
    <material>Gazebo/Green</material>
    <kp>1000000.0</kp>
    <!-- kp and kd for rubber -->
    <kd>100.0</kd>
    <mu1>1.0</mu1>
    <mu2>1.0</mu2>
    <maxVel>1.0</maxVel>
    <minDepth>0.00</minDepth>
  </gazebo>
  <gazebo reference="right_wheel_front">
    <material>Gazebo/Green</material>
    <kp>1000000.0</kp>
    <!-- kp and kd for rubber -->
    <kd>100.0</kd>
    <mu1>1.0</mu1>
    <mu2>1.0</mu2>
    <maxVel>1.0</maxVel>
    <minDepth>0.00</minDepth>
  </gazebo>
  <gazebo reference="right_wheel_back">
    <material>Gazebo/Green</material>
    <kp>1000000.0</kp>
    <!-- kp and kd for rubber -->
    <kd>100.0</kd>
    <mu1>1.0</mu1>
    <mu2>1.0</mu2>
    <maxVel>1.0</maxVel>
    <minDepth>0.00</minDepth>
  </gazebo>
  <!--<gazebo reference="right_wheel">
		<material>Gazebo/Green</material>
	</gazebo>-->
  <gazebo reference="camera">
    <material>Gazebo/Red</material>
  </gazebo>
  <gazebo reference="chassis">
    <material>Gazebo/Blue</material>
  </gazebo>
  <gazebo>
    <plugin filename="libgazebo_ros_skid_steer_drive.so" name="skid_steer_drive_controller">
      <updateRate>10.0</updateRate>
      <robotNamespace>/atom</robotNamespace>
      <leftFrontJoint>left_wheel_hinge_front</leftFrontJoint>
      <rightFrontJoint>right_wheel_hinge_front</rightFrontJoint>
      <leftRearJoint>left_wheel_hinge_back</leftRearJoint>
      <rightRearJoint>right_wheel_hinge_back</rightRearJoint>
      <wheelSeparation>0.4</wheelSeparation>
      <wheelDiameter>0.2</wheelDiameter>
      <robotBaseFrame>robot_footprint</robotBaseFrame>
      <torque>10</torque>
      <topicName>cmd_vel</topicName>
      <odometryTopic>odom</odometryTopic>
      <odometryFrame>odom</odometryFrame>
      <commandTopic>cmd_vel</commandTopic>
      <topic_name_twist>cmd_vel</topic_name_twist>
      <topic_name_odometry>odom</topic_name_odometry>
      <topic_name_joint>joint</topic_name_joint>
      <broadcastTF>true</broadcastTF>
      <covariance_x>0.0001</covariance_x>
      <covariance_y>0.0001</covariance_y>
      <covariance_yaw>0.01</covariance_yaw>
    </plugin>
  </gazebo>
  <!-- camera -->
  <gazebo reference="camera">
    <sensor name="camera1" type="camera">
      <update_rate>30.0</update_rate>
      <camera name="head">
        <horizontal_fov>1.3962634</horizontal_fov>
        <image>
          <width>800</width>
          <height>800</height>
          <format>R8G8B8</format>
        </image>
        <clip>
          <near>0.02</near>
          <far>300</far>
        </clip>
      </camera>
      <plugin filename="libgazebo_ros_camera.so" name="camera_controller">
        <robotNamespace>/atom</robotNamespace>
        <alwaysOn>true</alwaysOn>
        <updateRate>0.0</updateRate>
        <cameraName>camera</cameraName>
        <imageTopicName>rgb/image_raw</imageTopicName>
        <cameraInfoTopicName>rgb/camera_info</cameraInfoTopicName>
        <frameName>camera</frameName>
        <hackBaseline>0.07</hackBaseline>
        <distortionK1>0.0</distortionK1>
        <distortionK2>0.0</distortionK2>
        <distortionK3>0.0</distortionK3>
        <distortionT1>0.0</distortionT1>
        <distortionT2>0.0</distortionT2>
      </plugin>
    </sensor>
  </gazebo>
  <!-- hokuyo -->
  <gazebo reference="hokuyo">
    <sensor name="head_hokuyo_sensor" type="ray">
      <pose>0 0 0 0 0 0</pose>
      <visualize>false</visualize>
      <update_rate>40</update_rate>
      <ray>
        <scan>
          <horizontal>
            <samples>720</samples>
            <resolution>1</resolution>
            <min_angle>-1.570796</min_angle>
            <max_angle>1.570796</max_angle>
          </horizontal>
        </scan>
        <range>
          <min>0.10</min>
          <max>30.0</max>
          <resolution>0.01</resolution>
        </range>
        <noise>
          <type>gaussian</type>
          <!-- Noise parameters based on published spec for Hokuyo laser
               achieving "+-30mm" accuracy at range < 10m.  A mean of 0.0m and
               stddev of 0.01m will put 99.7% of samples within 0.03m of the true
               reading. -->
          <mean>0.0</mean>
          <stddev>0.01</stddev>
        </noise>
      </ray>
      <plugin filename="libgazebo_ros_laser.so" name="gazebo_ros_head_hokuyo_controller">
        <topicName>/scan</topicName>
        <frameName>hokuyo</frameName>
        <robotNamespace>/atom</robotNamespace>
      </plugin>
    </sensor>
  </gazebo>
  <gazebo reference="Livox_Mid40">
    <sensor name="laser_Livox_Mid40" type="ray">
      <pose>0 0 0 0 0 0</pose>
      <visualize>True</visualize>
      <update_rate>10</update_rate>
      <!-- This ray plgin is only for visualization. -->
      <plugin filename="liblivox_laser_simulation.so" name="gazebo_ros_laser_controller">
        <ray>
          <scan>
            <horizontal>
              <samples>100</samples>
              <resolution>1</resolution>
              <min_angle>-0.712966397222</min_angle>
              <max_angle>0.712966397222</max_angle>
            </horizontal>
            <vertical>
              <samples>50</samples>
              <resolution>1</resolution>
              <min_angle>-0.219038636111</min_angle>
              <max_angle>0.219038636111</max_angle>
            </vertical>
          </scan>
          <range>
            <min>0.1</min>
            <max>200.0</max>
            <resolution>0.002</resolution>
          </range>
          <noise>
            <type>gaussian</type>
            <mean>0.0</mean>
            <stddev>0.01</stddev>
          </noise>
        </ray>
        <visualize>True</visualize>
        <samples>24000</samples>
        <downsample>1</downsample>
        <csv_file_name>package://livox_laser_simulation/scan_mode/mid40.csv</csv_file_name>
        <ros_topic>scan</ros_topic>
      </plugin>
    </sensor>
  </gazebo>
</robot>

