<sdf version='1.7'>
  <world name='default'>
    <light name='sun' type='directional'>
      <cast_shadows>1</cast_shadows>
      <pose>0 0 10 0 -0 0</pose>
      <diffuse>0.8 0.8 0.8 1</diffuse>
      <specular>0.2 0.2 0.2 1</specular>
      <attenuation>
        <range>1000</range>
        <constant>0.9</constant>
        <linear>0.01</linear>
        <quadratic>0.001</quadratic>
      </attenuation>
      <direction>-0.5 0.1 -0.9</direction>
      <spot>
        <inner_angle>0</inner_angle>
        <outer_angle>0</outer_angle>
        <falloff>0</falloff>
      </spot>
    </light>
    <model name='ground_plane'>
      <static>1</static>
      <link name='link'>
        <collision name='collision'>
          <geometry>
            <plane>
              <normal>0 0 1</normal>
              <size>100 100</size>
            </plane>
          </geometry>
          <surface>
            <contact>
              <collide_bitmask>65535</collide_bitmask>
              <ode/>
            </contact>
            <friction>
              <ode>
                <mu>100</mu>
                <mu2>50</mu2>
              </ode>
              <torsional>
                <ode/>
              </torsional>
            </friction>
            <bounce/>
          </surface>
          <max_contacts>10</max_contacts>
        </collision>
        <visual name='visual'>
          <cast_shadows>0</cast_shadows>
          <geometry>
            <plane>
              <normal>0 0 1</normal>
              <size>100 100</size>
            </plane>
          </geometry>
          <material>
            <script>
              <uri>file://media/materials/scripts/gazebo.material</uri>
              <name>Gazebo/Grey</name>
            </script>
          </material>
        </visual>
        <self_collide>0</self_collide>
        <enable_wind>0</enable_wind>
        <kinematic>0</kinematic>
      </link>
    </model>
    <gravity>0 0 -9.8</gravity>
    <magnetic_field>6e-06 2.3e-05 -4.2e-05</magnetic_field>
    <atmosphere type='adiabatic'/>
    <physics type='ode'>
      <max_step_size>0.001</max_step_size>
      <real_time_factor>1</real_time_factor>
      <real_time_update_rate>1000</real_time_update_rate>
    </physics>
    <scene>
      <ambient>0.4 0.4 0.4 1</ambient>
      <background>0.7 0.7 0.7 1</background>
      <shadows>1</shadows>
    </scene>
    <wind/>
    <spherical_coordinates>
      <surface_model>EARTH_WGS84</surface_model>
      <latitude_deg>0</latitude_deg>
      <longitude_deg>0</longitude_deg>
      <elevation>0</elevation>
      <heading_deg>0</heading_deg>
    </spherical_coordinates>
    <model name='office.world'>
      <pose>8.27702 4.10574 0 0 -0 0</pose>
      <link name='Wall_11'>
        <collision name='Wall_11_Collision'>
          <geometry>
            <box>
              <size>22.75 0.15 2.5</size>
            </box>
          </geometry>
          <pose>0 0 1.25 0 -0 0</pose>
          <max_contacts>10</max_contacts>
          <surface>
            <contact>
              <ode/>
            </contact>
            <bounce/>
            <friction>
              <torsional>
                <ode/>
              </torsional>
              <ode/>
            </friction>
          </surface>
        </collision>
        <visual name='Wall_11_Visual'>
          <pose>0 0 1.25 0 -0 0</pose>
          <geometry>
            <box>
              <size>22.75 0.15 2.5</size>
            </box>
          </geometry>
          <material>
            <script>
              <uri>file://media/materials/scripts/gazebo.material</uri>
              <name>Gazebo/Grey</name>
            </script>
            <ambient>1 1 1 1</ambient>
          </material>
          <meta>
            <layer>0</layer>
          </meta>
        </visual>
        <pose>0.015161 6.425 0 0 -0 3.14159</pose>
        <self_collide>0</self_collide>
        <enable_wind>0</enable_wind>
        <kinematic>0</kinematic>
      </link>
      <link name='Wall_15'>
        <collision name='Wall_15_Collision'>
          <geometry>
            <box>
              <size>8.75 0.15 2.5</size>
            </box>
          </geometry>
          <pose>0 0 1.25 0 -0 0</pose>
          <max_contacts>10</max_contacts>
          <surface>
            <contact>
              <ode/>
            </contact>
            <bounce/>
            <friction>
              <torsional>
                <ode/>
              </torsional>
              <ode/>
            </friction>
          </surface>
        </collision>
        <visual name='Wall_15_Visual'>
          <pose>0 0 1.25 0 -0 0</pose>
          <geometry>
            <box>
              <size>8.75 0.15 2.5</size>
            </box>
          </geometry>
          <material>
            <script>
              <uri>file://media/materials/scripts/gazebo.material</uri>
              <name>Gazebo/Grey</name>
            </script>
            <ambient>1 1 1 1</ambient>
          </material>
          <meta>
            <layer>0</layer>
          </meta>
        </visual>
        <pose>-5.08854 2.04563 0 0 -0 -1.5708</pose>
        <self_collide>0</self_collide>
        <enable_wind>0</enable_wind>
        <kinematic>0</kinematic>
      </link>
      <link name='Wall_17'>
        <collision name='Wall_17_Collision'>
          <geometry>
            <box>
              <size>2.5 0.15 2.5</size>
            </box>
          </geometry>
          <pose>0 0 1.25 0 -0 0</pose>
          <max_contacts>10</max_contacts>
          <surface>
            <contact>
              <ode/>
            </contact>
            <bounce/>
            <friction>
              <torsional>
                <ode/>
              </torsional>
              <ode/>
            </friction>
          </surface>
        </collision>
        <visual name='Wall_17_Visual'>
          <pose>0 0 1.25 0 -0 0</pose>
          <geometry>
            <box>
              <size>2.5 0.15 2.5</size>
            </box>
          </geometry>
          <material>
            <script>
              <uri>file://media/materials/scripts/gazebo.material</uri>
              <name>Gazebo/Grey</name>
            </script>
            <ambient>1 1 1 1</ambient>
          </material>
          <meta>
            <layer>0</layer>
          </meta>
        </visual>
        <pose>-2.75356 2.83565 0 0 -0 -1.5708</pose>
        <self_collide>0</self_collide>
        <enable_wind>0</enable_wind>
        <kinematic>0</kinematic>
      </link>
      <link name='Wall_18'>
        <collision name='Wall_18_Collision'>
          <geometry>
            <box>
              <size>2.25 0.15 2.5</size>
            </box>
          </geometry>
          <pose>0 0 1.25 0 -0 0</pose>
          <max_contacts>10</max_contacts>
          <surface>
            <contact>
              <ode/>
            </contact>
            <bounce/>
            <friction>
              <torsional>
                <ode/>
              </torsional>
              <ode/>
            </friction>
          </surface>
        </collision>
        <visual name='Wall_18_Visual'>
          <pose>0 0 1.25 0 -0 0</pose>
          <geometry>
            <box>
              <size>2.25 0.15 2.5</size>
            </box>
          </geometry>
          <material>
            <script>
              <uri>file://media/materials/scripts/gazebo.material</uri>
              <name>Gazebo/Grey</name>
            </script>
            <ambient>1 1 1 1</ambient>
          </material>
          <meta>
            <layer>0</layer>
          </meta>
        </visual>
        <pose>-1.70356 1.66065 0 0 -0 0</pose>
        <self_collide>0</self_collide>
        <enable_wind>0</enable_wind>
        <kinematic>0</kinematic>
      </link>
      <link name='Wall_19'>
        <collision name='Wall_19_Collision'>
          <geometry>
            <box>
              <size>2.5 0.15 2.5</size>
            </box>
          </geometry>
          <pose>0 0 1.25 0 -0 0</pose>
          <max_contacts>10</max_contacts>
          <surface>
            <contact>
              <ode/>
            </contact>
            <bounce/>
            <friction>
              <torsional>
                <ode/>
              </torsional>
              <ode/>
            </friction>
          </surface>
        </collision>
        <visual name='Wall_19_Visual'>
          <pose>0 0 1.25 0 -0 0</pose>
          <geometry>
            <box>
              <size>2.5 0.15 2.5</size>
            </box>
          </geometry>
          <material>
            <script>
              <uri>file://media/materials/scripts/gazebo.material</uri>
              <name>Gazebo/Grey</name>
            </script>
            <ambient>1 1 1 1</ambient>
          </material>
          <meta>
            <layer>0</layer>
          </meta>
        </visual>
        <pose>-0.653558 2.83565 0 0 -0 1.5708</pose>
        <self_collide>0</self_collide>
        <enable_wind>0</enable_wind>
        <kinematic>0</kinematic>
      </link>
      <link name='Wall_20'>
        <collision name='Wall_20_Collision'>
          <geometry>
            <box>
              <size>2.25 0.15 2.5</size>
            </box>
          </geometry>
          <pose>0 0 1.25 0 -0 0</pose>
          <max_contacts>10</max_contacts>
          <surface>
            <contact>
              <ode/>
            </contact>
            <bounce/>
            <friction>
              <torsional>
                <ode/>
              </torsional>
              <ode/>
            </friction>
          </surface>
        </collision>
        <visual name='Wall_20_Visual'>
          <pose>0 0 1.25 0 -0 0</pose>
          <geometry>
            <box>
              <size>2.25 0.15 2.5</size>
            </box>
          </geometry>
          <material>
            <script>
              <uri>file://media/materials/scripts/gazebo.material</uri>
              <name>Gazebo/Grey</name>
            </script>
            <ambient>1 1 1 1</ambient>
          </material>
          <meta>
            <layer>0</layer>
          </meta>
        </visual>
        <pose>-1.70356 4.01065 0 0 -0 3.14159</pose>
        <self_collide>0</self_collide>
        <enable_wind>0</enable_wind>
        <kinematic>0</kinematic>
      </link>
      <link name='Wall_22'>
        <collision name='Wall_22_Collision'>
          <geometry>
            <box>
              <size>3 0.15 2.5</size>
            </box>
          </geometry>
          <pose>0 0 1.25 0 -0 0</pose>
          <max_contacts>10</max_contacts>
          <surface>
            <contact>
              <ode/>
            </contact>
            <bounce/>
            <friction>
              <torsional>
                <ode/>
              </torsional>
              <ode/>
            </friction>
          </surface>
        </collision>
        <visual name='Wall_22_Visual'>
          <pose>0 0 1.25 0 -0 0</pose>
          <geometry>
            <box>
              <size>3 0.15 2.5</size>
            </box>
          </geometry>
          <material>
            <script>
              <uri>file://media/materials/scripts/gazebo.material</uri>
              <name>Gazebo/Grey</name>
            </script>
            <ambient>1 1 1 1</ambient>
          </material>
          <meta>
            <layer>0</layer>
          </meta>
        </visual>
        <pose>2.27019 3.1611 0 0 -0 -1.5708</pose>
        <self_collide>0</self_collide>
        <enable_wind>0</enable_wind>
        <kinematic>0</kinematic>
      </link>
      <link name='Wall_23'>
        <collision name='Wall_23_Collision'>
          <geometry>
            <box>
              <size>2.25 0.15 2.5</size>
            </box>
          </geometry>
          <pose>0 0 1.25 0 -0 0</pose>
          <max_contacts>10</max_contacts>
          <surface>
            <contact>
              <ode/>
            </contact>
            <bounce/>
            <friction>
              <torsional>
                <ode/>
              </torsional>
              <ode/>
            </friction>
          </surface>
        </collision>
        <visual name='Wall_23_Visual'>
          <pose>0 0 1.25 0 -0 0</pose>
          <geometry>
            <box>
              <size>2.25 0.15 2.5</size>
            </box>
          </geometry>
          <material>
            <script>
              <uri>file://media/materials/scripts/gazebo.material</uri>
              <name>Gazebo/Grey</name>
            </script>
            <ambient>1 1 1 1</ambient>
          </material>
          <meta>
            <layer>0</layer>
          </meta>
        </visual>
        <pose>3.32019 1.7361 0 0 -0 0</pose>
        <self_collide>0</self_collide>
        <enable_wind>0</enable_wind>
        <kinematic>0</kinematic>
      </link>
      <link name='Wall_24'>
        <collision name='Wall_24_Collision'>
          <geometry>
            <box>
              <size>3 0.15 2.5</size>
            </box>
          </geometry>
          <pose>0 0 1.25 0 -0 0</pose>
          <max_contacts>10</max_contacts>
          <surface>
            <contact>
              <ode/>
            </contact>
            <bounce/>
            <friction>
              <torsional>
                <ode/>
              </torsional>
              <ode/>
            </friction>
          </surface>
        </collision>
        <visual name='Wall_24_Visual'>
          <pose>0 0 1.25 0 -0 0</pose>
          <geometry>
            <box>
              <size>3 0.15 2.5</size>
            </box>
          </geometry>
          <material>
            <script>
              <uri>file://media/materials/scripts/gazebo.material</uri>
              <name>Gazebo/Grey</name>
            </script>
            <ambient>1 1 1 1</ambient>
          </material>
          <meta>
            <layer>0</layer>
          </meta>
        </visual>
        <pose>4.37019 3.1611 0 0 -0 1.5708</pose>
        <self_collide>0</self_collide>
        <enable_wind>0</enable_wind>
        <kinematic>0</kinematic>
      </link>
      <link name='Wall_25'>
        <collision name='Wall_25_Collision'>
          <geometry>
            <box>
              <size>2.25 0.15 2.5</size>
            </box>
          </geometry>
          <pose>0 0 1.25 0 -0 0</pose>
          <max_contacts>10</max_contacts>
          <surface>
            <contact>
              <ode/>
            </contact>
            <bounce/>
            <friction>
              <torsional>
                <ode/>
              </torsional>
              <ode/>
            </friction>
          </surface>
        </collision>
        <visual name='Wall_25_Visual'>
          <pose>0 0 1.25 0 -0 0</pose>
          <geometry>
            <box>
              <size>2.25 0.15 2.5</size>
            </box>
          </geometry>
          <material>
            <script>
              <uri>file://media/materials/scripts/gazebo.material</uri>
              <name>Gazebo/Grey</name>
            </script>
            <ambient>1 1 1 1</ambient>
          </material>
          <meta>
            <layer>0</layer>
          </meta>
        </visual>
        <pose>3.32019 4.5861 0 0 -0 3.14159</pose>
        <self_collide>0</self_collide>
        <enable_wind>0</enable_wind>
        <kinematic>0</kinematic>
      </link>
      <link name='Wall_27'>
        <collision name='Wall_27_Collision'>
          <geometry>
            <box>
              <size>2.5 0.15 2.5</size>
            </box>
          </geometry>
          <pose>0 0 1.25 0 -0 0</pose>
          <max_contacts>10</max_contacts>
          <surface>
            <contact>
              <ode/>
            </contact>
            <bounce/>
            <friction>
              <torsional>
                <ode/>
              </torsional>
              <ode/>
            </friction>
          </surface>
        </collision>
        <visual name='Wall_27_Visual'>
          <pose>0 0 1.25 0 -0 0</pose>
          <geometry>
            <box>
              <size>2.5 0.15 2.5</size>
            </box>
          </geometry>
          <material>
            <script>
              <uri>file://media/materials/scripts/gazebo.material</uri>
              <name>Gazebo/Grey</name>
            </script>
            <ambient>1 1 1 1</ambient>
          </material>
          <meta>
            <layer>0</layer>
          </meta>
        </visual>
        <pose>6.94016 2.97716 0 0 -0 -1.5708</pose>
        <self_collide>0</self_collide>
        <enable_wind>0</enable_wind>
        <kinematic>0</kinematic>
      </link>
      <link name='Wall_28'>
        <collision name='Wall_28_Collision'>
          <geometry>
            <box>
              <size>2.64151 0.15 2.5</size>
            </box>
          </geometry>
          <pose>0 0 1.25 0 -0 0</pose>
          <max_contacts>10</max_contacts>
          <surface>
            <contact>
              <ode/>
            </contact>
            <bounce/>
            <friction>
              <torsional>
                <ode/>
              </torsional>
              <ode/>
            </friction>
          </surface>
        </collision>
        <visual name='Wall_28_Visual'>
          <pose>0 0 1.25 0 -0 0</pose>
          <geometry>
            <box>
              <size>2.64151 0.15 2.5</size>
            </box>
          </geometry>
          <material>
            <script>
              <uri>file://media/materials/scripts/gazebo.material</uri>
              <name>Gazebo/Grey</name>
            </script>
            <ambient>1 1 1 1</ambient>
          </material>
          <meta>
            <layer>0</layer>
          </meta>
        </visual>
        <pose>8.18592 1.80216 0 0 -0 0</pose>
        <self_collide>0</self_collide>
        <enable_wind>0</enable_wind>
        <kinematic>0</kinematic>
      </link>
      <link name='Wall_29'>
        <collision name='Wall_29_Collision'>
          <geometry>
            <box>
              <size>2.5 0.15 2.5</size>
            </box>
          </geometry>
          <pose>0 0 1.25 0 -0 0</pose>
          <max_contacts>10</max_contacts>
          <surface>
            <contact>
              <ode/>
            </contact>
            <bounce/>
            <friction>
              <torsional>
                <ode/>
              </torsional>
              <ode/>
            </friction>
          </surface>
        </collision>
        <visual name='Wall_29_Visual'>
          <pose>0 0 1.25 0 -0 0</pose>
          <geometry>
            <box>
              <size>2.5 0.15 2.5</size>
            </box>
          </geometry>
          <material>
            <script>
              <uri>file://media/materials/scripts/gazebo.material</uri>
              <name>Gazebo/Grey</name>
            </script>
            <ambient>1 1 1 1</ambient>
          </material>
          <meta>
            <layer>0</layer>
          </meta>
        </visual>
        <pose>9.36092 2.97716 0 0 -0 1.5708</pose>
        <self_collide>0</self_collide>
        <enable_wind>0</enable_wind>
        <kinematic>0</kinematic>
      </link>
      <link name='Wall_30'>
        <collision name='Wall_30_Collision'>
          <geometry>
            <box>
              <size>2.57076 0.15 2.5</size>
            </box>
          </geometry>
          <pose>0 0 1.25 0 -0 0</pose>
          <max_contacts>10</max_contacts>
          <surface>
            <contact>
              <ode/>
            </contact>
            <bounce/>
            <friction>
              <torsional>
                <ode/>
              </torsional>
              <ode/>
            </friction>
          </surface>
        </collision>
        <visual name='Wall_30_Visual'>
          <pose>0 0 1.25 0 -0 0</pose>
          <geometry>
            <box>
              <size>2.57076 0.15 2.5</size>
            </box>
          </geometry>
          <material>
            <script>
              <uri>file://media/materials/scripts/gazebo.material</uri>
              <name>Gazebo/Grey</name>
            </script>
            <ambient>1 1 1 1</ambient>
          </material>
          <meta>
            <layer>0</layer>
          </meta>
        </visual>
        <pose>8.15054 4.15216 0 0 -0 3.14159</pose>
        <self_collide>0</self_collide>
        <enable_wind>0</enable_wind>
        <kinematic>0</kinematic>
      </link>
      <link name='Wall_32'>
        <collision name='Wall_32_Collision'>
          <geometry>
            <box>
              <size>2.5 0.15 2.5</size>
            </box>
          </geometry>
          <pose>0 0 1.25 0 -0 0</pose>
          <max_contacts>10</max_contacts>
          <surface>
            <contact>
              <ode/>
            </contact>
            <bounce/>
            <friction>
              <torsional>
                <ode/>
              </torsional>
              <ode/>
            </friction>
          </surface>
        </collision>
        <visual name='Wall_32_Visual'>
          <pose>0 0 1.25 0 -0 0</pose>
          <geometry>
            <box>
              <size>2.5 0.15 2.5</size>
            </box>
          </geometry>
          <material>
            <script>
              <uri>file://media/materials/scripts/gazebo.material</uri>
              <name>Gazebo/Grey</name>
            </script>
            <ambient>1 1 1 1</ambient>
          </material>
          <meta>
            <layer>0</layer>
          </meta>
        </visual>
        <pose>-2.54129 -1.48053 0 0 -0 -1.5708</pose>
        <self_collide>0</self_collide>
        <enable_wind>0</enable_wind>
        <kinematic>0</kinematic>
      </link>
      <link name='Wall_33'>
        <collision name='Wall_33_Collision'>
          <geometry>
            <box>
              <size>2.5 0.15 2.5</size>
            </box>
          </geometry>
          <pose>0 0 1.25 0 -0 0</pose>
          <max_contacts>10</max_contacts>
          <surface>
            <contact>
              <ode/>
            </contact>
            <bounce/>
            <friction>
              <torsional>
                <ode/>
              </torsional>
              <ode/>
            </friction>
          </surface>
        </collision>
        <visual name='Wall_33_Visual'>
          <pose>0 0 1.25 0 -0 0</pose>
          <geometry>
            <box>
              <size>2.5 0.15 2.5</size>
            </box>
          </geometry>
          <material>
            <script>
              <uri>file://media/materials/scripts/gazebo.material</uri>
              <name>Gazebo/Grey</name>
            </script>
            <ambient>1 1 1 1</ambient>
          </material>
          <meta>
            <layer>0</layer>
          </meta>
        </visual>
        <pose>-1.36629 -2.65553 0 0 -0 0</pose>
        <self_collide>0</self_collide>
        <enable_wind>0</enable_wind>
        <kinematic>0</kinematic>
      </link>
      <link name='Wall_34'>
        <collision name='Wall_34_Collision'>
          <geometry>
            <box>
              <size>2.5 0.15 2.5</size>
            </box>
          </geometry>
          <pose>0 0 1.25 0 -0 0</pose>
          <max_contacts>10</max_contacts>
          <surface>
            <contact>
              <ode/>
            </contact>
            <bounce/>
            <friction>
              <torsional>
                <ode/>
              </torsional>
              <ode/>
            </friction>
          </surface>
        </collision>
        <visual name='Wall_34_Visual'>
          <pose>0 0 1.25 0 -0 0</pose>
          <geometry>
            <box>
              <size>2.5 0.15 2.5</size>
            </box>
          </geometry>
          <material>
            <script>
              <uri>file://media/materials/scripts/gazebo.material</uri>
              <name>Gazebo/Grey</name>
            </script>
            <ambient>1 1 1 1</ambient>
          </material>
          <meta>
            <layer>0</layer>
          </meta>
        </visual>
        <pose>-0.191286 -1.48053 0 0 -0 1.5708</pose>
        <self_collide>0</self_collide>
        <enable_wind>0</enable_wind>
        <kinematic>0</kinematic>
      </link>
      <link name='Wall_35'>
        <collision name='Wall_35_Collision'>
          <geometry>
            <box>
              <size>2.5 0.15 2.5</size>
            </box>
          </geometry>
          <pose>0 0 1.25 0 -0 0</pose>
          <max_contacts>10</max_contacts>
          <surface>
            <contact>
              <ode/>
            </contact>
            <bounce/>
            <friction>
              <torsional>
                <ode/>
              </torsional>
              <ode/>
            </friction>
          </surface>
        </collision>
        <visual name='Wall_35_Visual'>
          <pose>0 0 1.25 0 -0 0</pose>
          <geometry>
            <box>
              <size>2.5 0.15 2.5</size>
            </box>
          </geometry>
          <material>
            <script>
              <uri>file://media/materials/scripts/gazebo.material</uri>
              <name>Gazebo/Grey</name>
            </script>
            <ambient>1 1 1 1</ambient>
          </material>
          <meta>
            <layer>0</layer>
          </meta>
        </visual>
        <pose>-1.36629 -0.305535 0 0 -0 3.14159</pose>
        <self_collide>0</self_collide>
        <enable_wind>0</enable_wind>
        <kinematic>0</kinematic>
      </link>
      <link name='Wall_37'>
        <collision name='Wall_37_Collision'>
          <geometry>
            <box>
              <size>2.5 0.15 2.5</size>
            </box>
          </geometry>
          <pose>0 0 1.25 0 -0 0</pose>
          <max_contacts>10</max_contacts>
          <surface>
            <contact>
              <ode/>
            </contact>
            <bounce/>
            <friction>
              <torsional>
                <ode/>
              </torsional>
              <ode/>
            </friction>
          </surface>
        </collision>
        <visual name='Wall_37_Visual'>
          <pose>0 0 1.25 0 -0 0</pose>
          <geometry>
            <box>
              <size>2.5 0.15 2.5</size>
            </box>
          </geometry>
          <material>
            <script>
              <uri>file://media/materials/scripts/gazebo.material</uri>
              <name>Gazebo/Grey</name>
            </script>
            <ambient>1 1 1 1</ambient>
          </material>
          <meta>
            <layer>0</layer>
          </meta>
        </visual>
        <pose>2.62398 -1.40978 0 0 -0 -1.5708</pose>
        <self_collide>0</self_collide>
        <enable_wind>0</enable_wind>
        <kinematic>0</kinematic>
      </link>
      <link name='Wall_38'>
        <collision name='Wall_38_Collision'>
          <geometry>
            <box>
              <size>6 0.15 2.5</size>
            </box>
          </geometry>
          <pose>0 0 1.25 0 -0 0</pose>
          <max_contacts>10</max_contacts>
          <surface>
            <contact>
              <ode/>
            </contact>
            <bounce/>
            <friction>
              <torsional>
                <ode/>
              </torsional>
              <ode/>
            </friction>
          </surface>
        </collision>
        <visual name='Wall_38_Visual'>
          <pose>0 0 1.25 0 -0 0</pose>
          <geometry>
            <box>
              <size>6 0.15 2.5</size>
            </box>
          </geometry>
          <material>
            <script>
              <uri>file://media/materials/scripts/gazebo.material</uri>
              <name>Gazebo/Grey</name>
            </script>
            <ambient>1 1 1 1</ambient>
          </material>
          <meta>
            <layer>0</layer>
          </meta>
        </visual>
        <pose>5.54898 -2.58478 0 0 -0 0</pose>
        <self_collide>0</self_collide>
        <enable_wind>0</enable_wind>
        <kinematic>0</kinematic>
      </link>
      <link name='Wall_39'>
        <collision name='Wall_39_Collision'>
          <geometry>
            <box>
              <size>2.5 0.15 2.5</size>
            </box>
          </geometry>
          <pose>0 0 1.25 0 -0 0</pose>
          <max_contacts>10</max_contacts>
          <surface>
            <contact>
              <ode/>
            </contact>
            <bounce/>
            <friction>
              <torsional>
                <ode/>
              </torsional>
              <ode/>
            </friction>
          </surface>
        </collision>
        <visual name='Wall_39_Visual'>
          <pose>0 0 1.25 0 -0 0</pose>
          <geometry>
            <box>
              <size>2.5 0.15 2.5</size>
            </box>
          </geometry>
          <material>
            <script>
              <uri>file://media/materials/scripts/gazebo.material</uri>
              <name>Gazebo/Grey</name>
            </script>
            <ambient>1 1 1 1</ambient>
          </material>
          <meta>
            <layer>0</layer>
          </meta>
        </visual>
        <pose>8.47398 -1.40978 0 0 -0 1.5708</pose>
        <self_collide>0</self_collide>
        <enable_wind>0</enable_wind>
        <kinematic>0</kinematic>
      </link>
      <link name='Wall_40'>
        <collision name='Wall_40_Collision'>
          <geometry>
            <box>
              <size>6 0.15 2.5</size>
            </box>
          </geometry>
          <pose>0 0 1.25 0 -0 0</pose>
          <max_contacts>10</max_contacts>
          <surface>
            <contact>
              <ode/>
            </contact>
            <bounce/>
            <friction>
              <torsional>
                <ode/>
              </torsional>
              <ode/>
            </friction>
          </surface>
        </collision>
        <visual name='Wall_40_Visual'>
          <pose>0 0 1.25 0 -0 0</pose>
          <geometry>
            <box>
              <size>6 0.15 2.5</size>
            </box>
          </geometry>
          <material>
            <script>
              <uri>file://media/materials/scripts/gazebo.material</uri>
              <name>Gazebo/Grey</name>
            </script>
            <ambient>1 1 1 1</ambient>
          </material>
          <meta>
            <layer>0</layer>
          </meta>
        </visual>
        <pose>5.54898 -0.234777 0 0 -0 3.14159</pose>
        <self_collide>0</self_collide>
        <enable_wind>0</enable_wind>
        <kinematic>0</kinematic>
      </link>
      <link name='Wall_42'>
        <collision name='Wall_42_Collision'>
          <geometry>
            <box>
              <size>1.5 0.15 2.5</size>
            </box>
          </geometry>
          <pose>0 0 1.25 0 -0 0</pose>
          <max_contacts>10</max_contacts>
          <surface>
            <contact>
              <ode/>
            </contact>
            <bounce/>
            <friction>
              <torsional>
                <ode/>
              </torsional>
              <ode/>
            </friction>
          </surface>
        </collision>
        <visual name='Wall_42_Visual'>
          <pose>0 0 1.25 0 -0 0</pose>
          <geometry>
            <box>
              <size>1.5 0.15 2.5</size>
            </box>
          </geometry>
          <material>
            <script>
              <uri>file://media/materials/scripts/gazebo.material</uri>
              <name>Gazebo/Grey</name>
            </script>
            <ambient>1 1 1 1</ambient>
          </material>
          <meta>
            <layer>0</layer>
          </meta>
        </visual>
        <pose>-5.4968 3.14305 0 0 -0 -2.0944</pose>
        <self_collide>0</self_collide>
        <enable_wind>0</enable_wind>
        <kinematic>0</kinematic>
      </link>
      <link name='Wall_43'>
        <collision name='Wall_43_Collision'>
          <geometry>
            <box>
              <size>1 0.15 2.5</size>
            </box>
          </geometry>
          <pose>0 0 1.25 0 -0 0</pose>
          <max_contacts>10</max_contacts>
          <surface>
            <contact>
              <ode/>
            </contact>
            <bounce/>
            <friction>
              <torsional>
                <ode/>
              </torsional>
              <ode/>
            </friction>
          </surface>
        </collision>
        <visual name='Wall_43_Visual'>
          <pose>0 0 1.25 0 -0 0</pose>
          <geometry>
            <box>
              <size>1 0.15 2.5</size>
            </box>
          </geometry>
          <material>
            <script>
              <uri>file://media/materials/scripts/gazebo.material</uri>
              <name>Gazebo/Grey</name>
            </script>
            <ambient>1 1 1 1</ambient>
          </material>
          <meta>
            <layer>0</layer>
          </meta>
        </visual>
        <pose>-5.53378 2.25796 0 0 -0 -0.785398</pose>
        <self_collide>0</self_collide>
        <enable_wind>0</enable_wind>
        <kinematic>0</kinematic>
      </link>
      <link name='Wall_44'>
        <collision name='Wall_44_Collision'>
          <geometry>
            <box>
              <size>1.5 0.15 2.5</size>
            </box>
          </geometry>
          <pose>0 0 1.25 0 -0 0</pose>
          <max_contacts>10</max_contacts>
          <surface>
            <contact>
              <ode/>
            </contact>
            <bounce/>
            <friction>
              <torsional>
                <ode/>
              </torsional>
              <ode/>
            </friction>
          </surface>
        </collision>
        <visual name='Wall_44_Visual'>
          <pose>0 0 1.25 0 -0 0</pose>
          <geometry>
            <box>
              <size>1.5 0.15 2.5</size>
            </box>
          </geometry>
          <material>
            <script>
              <uri>file://media/materials/scripts/gazebo.material</uri>
              <name>Gazebo/Grey</name>
            </script>
            <ambient>1 1 1 1</ambient>
          </material>
          <meta>
            <layer>0</layer>
          </meta>
        </visual>
        <pose>-5.57076 1.37288 0 0 -0 -2.0944</pose>
        <self_collide>0</self_collide>
        <enable_wind>0</enable_wind>
        <kinematic>0</kinematic>
      </link>
      <link name='Wall_45'>
        <collision name='Wall_45_Collision'>
          <geometry>
            <box>
              <size>1.5 0.15 2.5</size>
            </box>
          </geometry>
          <pose>0 0 1.25 0 -0 0</pose>
          <max_contacts>10</max_contacts>
          <surface>
            <contact>
              <ode/>
            </contact>
            <bounce/>
            <friction>
              <torsional>
                <ode/>
              </torsional>
              <ode/>
            </friction>
          </surface>
        </collision>
        <visual name='Wall_45_Visual'>
          <pose>0 0 1.25 0 -0 0</pose>
          <geometry>
            <box>
              <size>1.5 0.15 2.5</size>
            </box>
          </geometry>
          <material>
            <script>
              <uri>file://media/materials/scripts/gazebo.material</uri>
              <name>Gazebo/Grey</name>
            </script>
            <ambient>1 1 1 1</ambient>
          </material>
          <meta>
            <layer>0</layer>
          </meta>
        </visual>
        <pose>-5.57076 0.203741 0 0 -0 -1.0472</pose>
        <self_collide>0</self_collide>
        <enable_wind>0</enable_wind>
        <kinematic>0</kinematic>
      </link>
      <link name='Wall_47'>
        <collision name='Wall_47_Collision'>
          <geometry>
            <box>
              <size>2.5 0.15 2.5</size>
            </box>
          </geometry>
          <pose>0 0 1.25 0 -0 0</pose>
          <max_contacts>10</max_contacts>
          <surface>
            <contact>
              <ode/>
            </contact>
            <bounce/>
            <friction>
              <torsional>
                <ode/>
              </torsional>
              <ode/>
            </friction>
          </surface>
        </collision>
        <visual name='Wall_47_Visual'>
          <pose>0 0 1.25 0 -0 0</pose>
          <geometry>
            <box>
              <size>2.5 0.15 2.5</size>
            </box>
          </geometry>
          <material>
            <script>
              <uri>file://media/materials/scripts/gazebo.material</uri>
              <name>Gazebo/Grey</name>
            </script>
            <ambient>1 1 1 1</ambient>
          </material>
          <meta>
            <layer>0</layer>
          </meta>
        </visual>
        <pose>-10.1402 -3.4896 0 0 -0 0</pose>
        <self_collide>0</self_collide>
        <enable_wind>0</enable_wind>
        <kinematic>0</kinematic>
      </link>
      <link name='Wall_48'>
        <collision name='Wall_48_Collision'>
          <geometry>
            <box>
              <size>3 0.15 2.5</size>
            </box>
          </geometry>
          <pose>0 0 1.25 0 -0 0</pose>
          <max_contacts>10</max_contacts>
          <surface>
            <contact>
              <ode/>
            </contact>
            <bounce/>
            <friction>
              <torsional>
                <ode/>
              </torsional>
              <ode/>
            </friction>
          </surface>
        </collision>
        <visual name='Wall_48_Visual'>
          <pose>0 0 1.25 0 -0 0</pose>
          <geometry>
            <box>
              <size>3 0.15 2.5</size>
            </box>
          </geometry>
          <material>
            <script>
              <uri>file://media/materials/scripts/gazebo.material</uri>
              <name>Gazebo/Grey</name>
            </script>
            <ambient>1 1 1 1</ambient>
          </material>
          <meta>
            <layer>0</layer>
          </meta>
        </visual>
        <pose>-8.96516 -4.9146 0 0 -0 -1.5708</pose>
        <self_collide>0</self_collide>
        <enable_wind>0</enable_wind>
        <kinematic>0</kinematic>
      </link>
      <link name='Wall_8'>
        <pose>-11.2848 -0 0 0 -0 -1.5708</pose>
        <visual name='Wall_8_Visual_0'>
          <pose>-6.011 0 1.25 0 -0 0</pose>
          <geometry>
            <box>
              <size>0.977998 0.15 2.5</size>
            </box>
          </geometry>
          <material>
            <script>
              <uri>file://media/materials/scripts/gazebo.material</uri>
              <name>Gazebo/Grey</name>
            </script>
            <ambient>1 1 1 1</ambient>
          </material>
          <meta>
            <layer>0</layer>
          </meta>
        </visual>
        <collision name='Wall_8_Collision_0'>
          <geometry>
            <box>
              <size>0.977998 0.15 2.5</size>
            </box>
          </geometry>
          <pose>-6.011 0 1.25 0 -0 0</pose>
          <max_contacts>10</max_contacts>
          <surface>
            <contact>
              <ode/>
            </contact>
            <bounce/>
            <friction>
              <torsional>
                <ode/>
              </torsional>
              <ode/>
            </friction>
          </surface>
        </collision>
        <visual name='Wall_8_Visual_1'>
          <pose>0.938999 0 1.25 0 -0 0</pose>
          <geometry>
            <box>
              <size>11.122 0.15 2.5</size>
            </box>
          </geometry>
          <material>
            <script>
              <uri>file://media/materials/scripts/gazebo.material</uri>
              <name>Gazebo/Grey</name>
            </script>
            <ambient>1 1 1 1</ambient>
          </material>
          <meta>
            <layer>0</layer>
          </meta>
        </visual>
        <collision name='Wall_8_Collision_1'>
          <geometry>
            <box>
              <size>11.122 0.15 2.5</size>
            </box>
          </geometry>
          <pose>0.938999 0 1.25 0 -0 0</pose>
          <max_contacts>10</max_contacts>
          <surface>
            <contact>
              <ode/>
            </contact>
            <bounce/>
            <friction>
              <torsional>
                <ode/>
              </torsional>
              <ode/>
            </friction>
          </surface>
        </collision>
        <visual name='Wall_8_Visual_2'>
          <pose>-5.072 0 2.25 0 -0 0</pose>
          <geometry>
            <box>
              <size>0.9 0.15 0.5</size>
            </box>
          </geometry>
          <material>
            <script>
              <uri>file://media/materials/scripts/gazebo.material</uri>
              <name>Gazebo/Grey</name>
            </script>
            <ambient>1 1 1 1</ambient>
          </material>
          <meta>
            <layer>0</layer>
          </meta>
        </visual>
        <collision name='Wall_8_Collision_2'>
          <geometry>
            <box>
              <size>0.9 0.15 0.5</size>
            </box>
          </geometry>
          <pose>-5.072 0 2.25 0 -0 0</pose>
          <max_contacts>10</max_contacts>
          <surface>
            <contact>
              <ode/>
            </contact>
            <bounce/>
            <friction>
              <torsional>
                <ode/>
              </torsional>
              <ode/>
            </friction>
          </surface>
        </collision>
        <self_collide>0</self_collide>
        <enable_wind>0</enable_wind>
        <kinematic>0</kinematic>
      </link>
      <link name='Wall_9'>
        <collision name='Wall_9_Collision'>
          <geometry>
            <box>
              <size>22.75 0.15 2.5</size>
            </box>
          </geometry>
          <pose>0 0 1.25 0 -0 0</pose>
          <max_contacts>10</max_contacts>
          <surface>
            <contact>
              <ode/>
            </contact>
            <bounce/>
            <friction>
              <torsional>
                <ode/>
              </torsional>
              <ode/>
            </friction>
          </surface>
        </collision>
        <visual name='Wall_9_Visual'>
          <pose>0 0 1.25 0 -0 0</pose>
          <geometry>
            <box>
              <size>22.75 0.15 2.5</size>
            </box>
          </geometry>
          <material>
            <script>
              <uri>file://media/materials/scripts/gazebo.material</uri>
              <name>Gazebo/Grey</name>
            </script>
            <ambient>1 1 1 1</ambient>
          </material>
          <meta>
            <layer>0</layer>
          </meta>
        </visual>
        <pose>0.015161 -6.425 0 0 -0 0</pose>
        <self_collide>0</self_collide>
        <enable_wind>0</enable_wind>
        <kinematic>0</kinematic>
      </link>
      <static>1</static>
    </model>
    <state world_name='default'>
      <sim_time>157 261000000</sim_time>
      <real_time>80 239159267</real_time>
      <wall_time>1682620584 703083487</wall_time>
      <iterations>69292</iterations>
      <model name='clifford'>
        <pose>0 0 -23308.8 0 -0 0</pose>
        <scale>1 1 1</scale>
        <link name='3d_lidar::link'>
          <pose>0.018055 -0.002618 0.655333 -0.002818 8.8e-05 0.039895</pose>
          <velocity>0.008291 0.007811 -0.000371 -0.016119 0.016541 -0.001396</velocity>
          <acceleration>19.2796 0.134237 -0.350762 2.3311 1.13552 1.12791</acceleration>
          <wrench>0.01928 0.000134 -0.000351 0 -0 0</wrench>
        </link>
        <link name='backAxle'>
          <pose>-0.305545 -0.087766 0.088086 0.301805 1.6e-05 1.61104</pose>
          <velocity>-0.001451 0.000522 0.000939 -0.005612 0.00898 -0.011142</velocity>
          <acceleration>0.014341 0.21964 -4.81095 1.73528 -0.572954 2.66642</acceleration>
          <wrench>0.001391 0.021303 -0.466609 0 -0 0</wrench>
        </link>
        <link name='backSteeringBar'>
          <pose>-0.33278 0.097045 0.099905 2.90874 5e-05 1.61104</pose>
          <velocity>-0.000648 0.005373 0.000568 -0.000216 0.000203 0.001115</velocity>
          <acceleration>1.52416 1.47649 0.044043 -0.38844 0.029216 0.292972</acceleration>
          <wrench>1.52416 1.47649 0.044043 0 -0 0</wrench>
        </link>
        <link name='base_footprint'>
          <pose>0 0 -23308.8 0 -0 0</pose>
          <velocity>0 0 -675.906 0 -0 0</velocity>
          <acceleration>0 0 -9.8 0 -0 0</acceleration>
          <wrench>0 0 -9.8 0 -0 0</wrench>
        </link>
        <link name='bli'>
          <pose>-0.299949 -0.000719 0.159091 0.272461 -0.051968 0.18703</pose>
          <velocity>9.9e-05 0.000828 0.000392 -0.300488 -0.060622 -0.019481</velocity>
          <acceleration>0.084456 -0.652653 0.018503 -2.75822 -0.62558 -0.210618</acceleration>
          <wrench>0.001692 -0.013075 0.000371 0 -0 0</wrench>
        </link>
        <link name='blo'>
          <pose>-0.31124 0.053619 0.088082 2.5655 -0.188456 -0.001293</pose>
          <velocity>0.000354 0.000594 0.000387 -0.01195 -0.000297 -0.007119</velocity>
          <acceleration>-0.61075 0.08478 0.164763 0.399601 0.10494 -2.82608</acceleration>
          <wrench>-0.007202 0.001 0.001943 0 -0 0</wrench>
        </link>
        <link name='blslower'>
          <pose>-0.307212 0.075049 0.104364 -2.32995 -0.509015 -0.116853</pose>
          <velocity>0.000731 0.000597 0.000255 -0.036172 -0.005385 -0.021181</velocity>
          <acceleration>-0.244985 0.165519 -2.2094 -2.08106 -0.627203 -1.86646</acceleration>
          <wrench>-0.002751 0.001859 -0.024814 0 -0 0</wrench>
        </link>
        <link name='blsupper'>
          <pose>-0.174115 0.059425 0.179151 -2.11027 0.509017 3.02474</pose>
          <velocity>0.000487 0.000371 0.001789 -0.035906 -0.005013 -0.021404</velocity>
          <acceleration>0.558281 -0.768539 6.40001 -0.937682 -1.40094 -2.87895</acceleration>
          <wrench>0.00627 -0.008632 0.071879 0 -0 0</wrench>
        </link>
        <link name='bltire'>
          <pose>-0.333583 0.117021 0.1 -2.33963 -2e-05 1.61109</pose>
          <velocity>0.000993 0.000694 0.000137 -0.006946 0.009911 0.010647</velocity>
          <acceleration>0.084366 0.060373 -2.30494 -1.26234 -1.07608 -2.22969</acceleration>
          <wrench>0.22363 0.160031 -6.10976 0 -0 0</wrench>
        </link>
        <link name='blwheel'>
          <pose>-0.332783 0.097038 0.100006 -2.83966 0.000123 1.61102</pose>
          <velocity>-0.001544 0.000726 0.000624 -0.00628 -0.001787 -0.028312</velocity>
          <acceleration>0.758685 0.134072 -1.72945 2.82586 -0.825684 2.17468</acceleration>
          <wrench>0.148239 0.026196 -0.337918 0 -0 0</wrench>
        </link>
        <link name='body'>
          <pose>0.018067 -0.004027 0.155335 -0.002818 8.8e-05 0.039895</pose>
          <velocity>1.3e-05 -0.000244 -0.00035 -0.01595 0.016538 -0.001416</velocity>
          <acceleration>-0.564117 0.062959 -0.349055 -0.246219 0.995287 1.09775</acceleration>
          <wrench>-0.679513 0.075838 -0.420458 0 -0 0</wrench>
        </link>
        <link name='bri'>
          <pose>-0.298675 -0.032699 0.159097 0.549645 -0.053228 -0.106705</pose>
          <velocity>0.000141 0.001001 0.000443 0.316812 -0.044561 0.012279</velocity>
          <acceleration>0.683886 0.273096 -0.706975 1.15931 -0.820533 0.55366</acceleration>
          <wrench>0.0137 0.005471 -0.014163 0 -0 0</wrench>
        </link>
        <link name='bro'>
          <pose>-0.080414 -0.069575 0.131517 1.85769 0.189974 -3.06096</pose>
          <velocity>-0.001471 -0.00051 0.002299 0.476036 0.032265 0.087349</velocity>
          <acceleration>-0.961163 0.077159 -1.36225 -2.46159 -0.022289 -1.90558</acceleration>
          <wrench>-0.011335 0.00091 -0.016064 0 -0 0</wrench>
        </link>
        <link name='brslower'>
          <pose>-0.299806 -0.108805 0.10437 1.1679 -0.511385 0.197929</pose>
          <velocity>-0.000365 0.000508 0.001238 0.036617 -0.006378 0.018066</velocity>
          <acceleration>-0.124376 1.34982 -5.82615 0.097742 -0.836957 1.39573</acceleration>
          <wrench>-0.001397 0.01516 -0.065434 0 -0 0</wrench>
        </link>
        <link name='brsupper'>
          <pose>-0.168451 -0.082461 0.179552 0.67506 0.511389 -2.94366</pose>
          <velocity>0.000339 0.00034 0.004019 0.037504 -0.006764 0.017217</velocity>
          <acceleration>1.32392 -0.397576 5.88349 0.909416 -1.3366 0.420356</acceleration>
          <wrench>0.014869 -0.004465 0.066078 0 -0 0</wrench>
        </link>
        <link name='brtire'>
          <pose>-0.31909 -0.242689 0.100001 -2.73848 1.6e-05 1.61105</pose>
          <velocity>0.002476 0.000726 0.000717 -0.006284 0.000631 0.02684</velocity>
          <acceleration>-0.071486 1.90332 -8.87904 -1.46516 -0.912301 -2.51168</acceleration>
          <wrench>-0.18949 5.04516 -23.5358 0 -0 0</wrench>
        </link>
        <link name='brwheel'>
          <pose>-0.323518 -0.132779 0.099997 2.84004 8e-06 -1.53056</pose>
          <velocity>-0.000364 0.000579 0.000544 -0.010338 -0.003068 0.025833</velocity>
          <acceleration>1.02996 2.00875 -7.92513 0.069785 0.498241 0.364792</acceleration>
          <wrench>0.201244 0.39249 -1.54849 0 -0 0</wrench>
        </link>
        <link name='fli'>
          <pose>0.334817 0.024685 0.159095 2.29278 -0.051838 3.03466</pose>
          <velocity>1.4e-05 -0.00346 0.002403 2.1358 0.416027 0.199549</velocity>
          <acceleration>-0.657922 -2.6918 2.53678 -2.65888 -0.054394 -3.06953</acceleration>
          <wrench>-0.01318 -0.053925 0.05082 0 -0 0</wrench>
        </link>
        <link name='flo'>
          <pose>0.341731 0.079748 0.088078 0.123594 -0.188423 -3.0602</pose>
          <velocity>0.000984 0.000997 0.005898 -1.29425 -0.145187 0.255399</velocity>
          <acceleration>-0.292226 1.03772 5.99637 -2.63317 -0.70459 -0.722905</acceleration>
          <wrench>-0.003446 0.012237 0.070712 0 -0 0</wrench>
        </link>
        <link name='flslower'>
          <pose>0.336011 0.100789 0.104361 -0.318491 -0.508843 -2.94452</pose>
          <velocity>0.000995 -5e-06 0.007201 -0.402607 -0.151022 0.236685</velocity>
          <acceleration>0.289706 -0.212189 16.2018 -0.368105 -0.707751 -0.592285</acceleration>
          <wrench>0.003254 -0.002383 0.181964 0 -0 0</wrench>
        </link>
        <link name='flsupper'>
          <pose>0.204584 0.074548 0.179123 1.33441 0.50884 0.19707</pose>
          <velocity>0.000524 -8.3e-05 -0.00472 -0.40271 -0.151305 0.23648</velocity>
          <acceleration>1.28161 0.975186 -5.54474 -0.12548 -0.138357 -0.158103</acceleration>
          <wrench>0.014394 0.010952 -0.062273 0 -0 0</wrench>
        </link>
        <link name='fltire'>
          <pose>0.358972 0.14473 0.1 -1.0915 -2e-06 1.60944</pose>
          <velocity>0.000641 5.8e-05 0.010014 -0.000569 0.006076 0.000886</velocity>
          <acceleration>0.714041 0.026931 23.0999 -3.01525 -1.15982 1.50124</acceleration>
          <wrench>1.89272 0.071386 61.2313 0 -0 0</wrench>
        </link>
        <link name='flwheel'>
          <pose>0.359743 0.124745 0.1 2.83974 -8.4e-05 1.60943</pose>
          <velocity>2e-05 1.5e-05 0.012084 0.002212 -0.028569 -0.001678</velocity>
          <acceleration>0.205288 -0.110967 26.8571 -1.86382 0.240725 2.64468</acceleration>
          <wrench>0.040111 -0.021682 5.24761 0 -0 0</wrench>
        </link>
        <link name='fri'>
          <pose>0.33608 -0.00729 0.159091 1.12302 -0.053173 -2.95473</pose>
          <velocity>0.00129 -0.003386 -0.000134 -0.122162 -0.031812 -0.009882</velocity>
          <acceleration>1.14678 -2.48216 0.52706 2.11992 1.24493 -1.47178</acceleration>
          <wrench>0.022974 -0.049726 0.010559 0 -0 0</wrench>
        </link>
        <link name='fro'>
          <pose>0.121449 -0.061517 0.131499 2.23497 0.189875 -0.000553</pose>
          <velocity>-0.000165 -0.000753 -0.001144 -0.006534 0.009154 0.008789</velocity>
          <acceleration>-1.48632 0.992356 -1.73348 -0.856111 1.46307 -2.76164</acceleration>
          <wrench>-0.017527 0.011702 -0.020442 0 -0 0</wrench>
        </link>
        <link name='frontAxle'>
          <pose>0.347317 -0.061642 0.08809 -0.301568 5.1e-05 1.61032</pose>
          <velocity>-0.000527 0.00094 -0.003185 0.064808 -0.003401 -0.01071</velocity>
          <acceleration>0.022887 -0.802751 8.92998 -0.967398 -0.703824 3.00401</acceleration>
          <wrench>0.00222 -0.077858 0.866109 0 -0 0</wrench>
        </link>
        <link name='frontSteeringBar'>
          <pose>0.359735 0.124549 0.099898 2.83998 0.000213 1.61039</pose>
          <velocity>-0.000427 0.000417 -0.000901 0.000363 3.9e-05 -3.7e-05</velocity>
          <acceleration>-1.33308 0.466409 -0.222912 0.562236 0.01482 0.249866</acceleration>
          <wrench>-1.33308 0.466409 -0.222912 0 -0 0</wrench>
        </link>
        <link name='frslower'>
          <pose>0.343279 -0.083068 0.104374 -0.826358 -0.511246 3.02395</pose>
          <velocity>-0.000544 -6.2e-05 -0.004839 -0.087379 0.026901 0.050085</velocity>
          <acceleration>-1.78656 0.238303 -2.24501 1.27442 -1.55621 3.06394</acceleration>
          <wrench>-0.020065 0.002676 -0.025214 0 -0 0</wrench>
        </link>
        <link name='frsupper'>
          <pose>0.210249 -0.067346 0.179522 1.84227 0.511247 -0.117642</pose>
          <velocity>0.000333 -0.000105 -0.002486 -0.087661 0.027018 0.049747</velocity>
          <acceleration>0.870174 0.755382 -7.56183 1.18813 -1.0983 3.06892</acceleration>
          <wrench>0.009773 0.008484 -0.084928 0 -0 0</wrench>
        </link>
        <link name='frtire'>
          <pose>0.373086 -0.214994 0.09999 -0.834811 -5e-06 1.60945</pose>
          <velocity>0.000243 5.5e-05 -0.009723 0.000738 0.009302 -0.000744</velocity>
          <acceleration>-0.458349 0.270363 -9.86885 -2.13989 -0.063377 1.09177</acceleration>
          <wrench>-1.21496 0.716657 -26.1596 0 -0 0</wrench>
        </link>
        <link name='frwheel'>
          <pose>0.368834 -0.105077 0.099993 0.301702 -1e-05 -1.53214</pose>
          <velocity>0.000382 5.1e-05 -0.010012 -3.4e-05 0.020262 -0.001554</velocity>
          <acceleration>-0.474884 0.246983 -10.4197 2.98647 0.493042 0.737909</acceleration>
          <wrench>-0.092788 0.048258 -2.03591 0 -0 0</wrench>
        </link>
        <link name='imu_gazebo::link'>
          <pose>0.018065 -0.003802 0.235334 -0.002818 8.8e-05 0.039895</pose>
          <velocity>0.001342 0.001042 -0.000352 -0.016086 0.016539 -0.001396</velocity>
          <acceleration>2.5992 0.073693 -0.350919 3.00919 1.11526 1.12805</acceleration>
          <wrench>0.002599 7.4e-05 -0.000351 0 -0 0</wrench>
        </link>
      </model>
      <model name='ground_plane'>
        <pose>0 0 0 0 -0 0</pose>
        <scale>1 1 1</scale>
        <link name='link'>
          <pose>0 0 0 0 -0 0</pose>
          <velocity>0 0 0 0 -0 0</velocity>
          <acceleration>0 0 0 0 -0 0</acceleration>
          <wrench>0 0 0 0 -0 0</wrench>
        </link>
      </model>
      <model name='office.world'>
        <pose>6.86394 4.79208 0 0 -0 0</pose>
        <scale>1 1 1</scale>
        <link name='Wall_11'>
          <pose>6.8791 11.2171 0 0 -0 3.14159</pose>
          <velocity>0 0 0 0 -0 0</velocity>
          <acceleration>0 0 0 0 -0 0</acceleration>
          <wrench>0 0 0 0 -0 0</wrench>
        </link>
        <link name='Wall_15'>
          <pose>1.7754 6.83771 0 0 0 -1.5708</pose>
          <velocity>0 0 0 0 -0 0</velocity>
          <acceleration>0 0 0 0 -0 0</acceleration>
          <wrench>0 0 0 0 -0 0</wrench>
        </link>
        <link name='Wall_17'>
          <pose>4.11038 7.62773 0 0 0 -1.5708</pose>
          <velocity>0 0 0 0 -0 0</velocity>
          <acceleration>0 0 0 0 -0 0</acceleration>
          <wrench>0 0 0 0 -0 0</wrench>
        </link>
        <link name='Wall_18'>
          <pose>5.16038 6.45273 0 0 -0 0</pose>
          <velocity>0 0 0 0 -0 0</velocity>
          <acceleration>0 0 0 0 -0 0</acceleration>
          <wrench>0 0 0 0 -0 0</wrench>
        </link>
        <link name='Wall_19'>
          <pose>6.21038 7.62773 0 0 -0 1.5708</pose>
          <velocity>0 0 0 0 -0 0</velocity>
          <acceleration>0 0 0 0 -0 0</acceleration>
          <wrench>0 0 0 0 -0 0</wrench>
        </link>
        <link name='Wall_20'>
          <pose>5.16038 8.80273 0 0 -0 3.14159</pose>
          <velocity>0 0 0 0 -0 0</velocity>
          <acceleration>0 0 0 0 -0 0</acceleration>
          <wrench>0 0 0 0 -0 0</wrench>
        </link>
        <link name='Wall_22'>
          <pose>9.13412 7.95318 0 0 0 -1.5708</pose>
          <velocity>0 0 0 0 -0 0</velocity>
          <acceleration>0 0 0 0 -0 0</acceleration>
          <wrench>0 0 0 0 -0 0</wrench>
        </link>
        <link name='Wall_23'>
          <pose>10.1841 6.52818 0 0 -0 0</pose>
          <velocity>0 0 0 0 -0 0</velocity>
          <acceleration>0 0 0 0 -0 0</acceleration>
          <wrench>0 0 0 0 -0 0</wrench>
        </link>
        <link name='Wall_24'>
          <pose>11.2341 7.95318 0 0 -0 1.5708</pose>
          <velocity>0 0 0 0 -0 0</velocity>
          <acceleration>0 0 0 0 -0 0</acceleration>
          <wrench>0 0 0 0 -0 0</wrench>
        </link>
        <link name='Wall_25'>
          <pose>10.1841 9.37818 0 0 -0 3.14159</pose>
          <velocity>0 0 0 0 -0 0</velocity>
          <acceleration>0 0 0 0 -0 0</acceleration>
          <wrench>0 0 0 0 -0 0</wrench>
        </link>
        <link name='Wall_27'>
          <pose>13.8041 7.76924 0 0 0 -1.5708</pose>
          <velocity>0 0 0 0 -0 0</velocity>
          <acceleration>0 0 0 0 -0 0</acceleration>
          <wrench>0 0 0 0 -0 0</wrench>
        </link>
        <link name='Wall_28'>
          <pose>15.0498 6.59424 0 0 -0 0</pose>
          <velocity>0 0 0 0 -0 0</velocity>
          <acceleration>0 0 0 0 -0 0</acceleration>
          <wrench>0 0 0 0 -0 0</wrench>
        </link>
        <link name='Wall_29'>
          <pose>16.2248 7.76924 0 0 -0 1.5708</pose>
          <velocity>0 0 0 0 -0 0</velocity>
          <acceleration>0 0 0 0 -0 0</acceleration>
          <wrench>0 0 0 0 -0 0</wrench>
        </link>
        <link name='Wall_30'>
          <pose>15.0145 8.94424 0 0 -0 3.14159</pose>
          <velocity>0 0 0 0 -0 0</velocity>
          <acceleration>0 0 0 0 -0 0</acceleration>
          <wrench>0 0 0 0 -0 0</wrench>
        </link>
        <link name='Wall_32'>
          <pose>4.32265 3.31155 0 0 0 -1.5708</pose>
          <velocity>0 0 0 0 -0 0</velocity>
          <acceleration>0 0 0 0 -0 0</acceleration>
          <wrench>0 0 0 0 -0 0</wrench>
        </link>
        <link name='Wall_33'>
          <pose>5.49765 2.13655 0 0 -0 0</pose>
          <velocity>0 0 0 0 -0 0</velocity>
          <acceleration>0 0 0 0 -0 0</acceleration>
          <wrench>0 0 0 0 -0 0</wrench>
        </link>
        <link name='Wall_34'>
          <pose>6.67265 3.31155 0 0 -0 1.5708</pose>
          <velocity>0 0 0 0 -0 0</velocity>
          <acceleration>0 0 0 0 -0 0</acceleration>
          <wrench>0 0 0 0 -0 0</wrench>
        </link>
        <link name='Wall_35'>
          <pose>5.49765 4.48655 0 0 -0 3.14159</pose>
          <velocity>0 0 0 0 -0 0</velocity>
          <acceleration>0 0 0 0 -0 0</acceleration>
          <wrench>0 0 0 0 -0 0</wrench>
        </link>
        <link name='Wall_37'>
          <pose>9.48792 3.3823 0 0 0 -1.5708</pose>
          <velocity>0 0 0 0 -0 0</velocity>
          <acceleration>0 0 0 0 -0 0</acceleration>
          <wrench>0 0 0 0 -0 0</wrench>
        </link>
        <link name='Wall_38'>
          <pose>12.4129 2.2073 0 0 -0 0</pose>
          <velocity>0 0 0 0 -0 0</velocity>
          <acceleration>0 0 0 0 -0 0</acceleration>
          <wrench>0 0 0 0 -0 0</wrench>
        </link>
        <link name='Wall_39'>
          <pose>15.3379 3.3823 0 0 -0 1.5708</pose>
          <velocity>0 0 0 0 -0 0</velocity>
          <acceleration>0 0 0 0 -0 0</acceleration>
          <wrench>0 0 0 0 -0 0</wrench>
        </link>
        <link name='Wall_40'>
          <pose>12.4129 4.5573 0 0 -0 3.14159</pose>
          <velocity>0 0 0 0 -0 0</velocity>
          <acceleration>0 0 0 0 -0 0</acceleration>
          <wrench>0 0 0 0 -0 0</wrench>
        </link>
        <link name='Wall_42'>
          <pose>1.36714 7.93513 0 0 0 -2.0944</pose>
          <velocity>0 0 0 0 -0 0</velocity>
          <acceleration>0 0 0 0 -0 0</acceleration>
          <wrench>0 0 0 0 -0 0</wrench>
        </link>
        <link name='Wall_43'>
          <pose>1.33016 7.05004 0 0 0 -0.785398</pose>
          <velocity>0 0 0 0 -0 0</velocity>
          <acceleration>0 0 0 0 -0 0</acceleration>
          <wrench>0 0 0 0 -0 0</wrench>
        </link>
        <link name='Wall_44'>
          <pose>1.29318 6.16496 0 0 0 -2.0944</pose>
          <velocity>0 0 0 0 -0 0</velocity>
          <acceleration>0 0 0 0 -0 0</acceleration>
          <wrench>0 0 0 0 -0 0</wrench>
        </link>
        <link name='Wall_45'>
          <pose>1.29318 4.99582 0 0 0 -1.0472</pose>
          <velocity>0 0 0 0 -0 0</velocity>
          <acceleration>0 0 0 0 -0 0</acceleration>
          <wrench>0 0 0 0 -0 0</wrench>
        </link>
        <link name='Wall_47'>
          <pose>-3.27626 1.30248 0 0 -0 0</pose>
          <velocity>0 0 0 0 -0 0</velocity>
          <acceleration>0 0 0 0 -0 0</acceleration>
          <wrench>0 0 0 0 -0 0</wrench>
        </link>
        <link name='Wall_48'>
          <pose>-2.10122 -0.122524 0 0 0 -1.5708</pose>
          <velocity>0 0 0 0 -0 0</velocity>
          <acceleration>0 0 0 0 -0 0</acceleration>
          <wrench>0 0 0 0 -0 0</wrench>
        </link>
        <link name='Wall_8'>
          <pose>-4.42086 4.79208 0 0 0 -1.5708</pose>
          <velocity>0 0 0 0 -0 0</velocity>
          <acceleration>0 0 0 0 -0 0</acceleration>
          <wrench>0 0 0 0 -0 0</wrench>
        </link>
        <link name='Wall_9'>
          <pose>6.8791 -1.63288 0 0 -0 0</pose>
          <velocity>0 0 0 0 -0 0</velocity>
          <acceleration>0 0 0 0 -0 0</acceleration>
          <wrench>0 0 0 0 -0 0</wrench>
        </link>
      </model>
      <light name='sun'>
        <pose>0 0 10 0 -0 0</pose>
      </light>
    </state>
    <gui fullscreen='0'>
      <camera name='user_camera'>
        <pose>-24.4505 -0.908688 41.5561 0 0.927642 0.164201</pose>
        <view_controller>orbit</view_controller>
        <projection_type>perspective</projection_type>
      </camera>
    </gui>
    <model name='clifford'>
      <link name='base_footprint'>
        <self_collide>0</self_collide>
        <inertial>
          <pose>0 0 0 0 -0 0</pose>
          <inertia>
            <ixx>1</ixx>
            <ixy>0</ixy>
            <ixz>0</ixz>
            <iyy>1</iyy>
            <iyz>0</iyz>
            <izz>1</izz>
          </inertia>
          <mass>1</mass>
        </inertial>
        <enable_wind>0</enable_wind>
        <kinematic>0</kinematic>
      </link>
      <link name='body'>
        <pose>0 0 0 0 -0 0</pose>
        <inertial>
          <pose>0 -0 0.000679 0 -0 0</pose>
          <mass>1.20456</mass>
          <inertia>
            <ixx>0.00136339</ixx>
            <ixy>-1.92982e-16</ixy>
            <ixz>-5.63833e-15</ixz>
            <iyy>0.0039261</iyy>
            <iyz>3.35564e-17</iyz>
            <izz>0.00436726</izz>
          </inertia>
        </inertial>
        <collision name='body_collision'>
          <pose>0 0 0 0 -0 0</pose>
          <geometry>
            <mesh>
              <scale>1 1 1</scale>
              <uri>model://meshes/body.STL</uri>
            </mesh>
          </geometry>
          <max_contacts>10</max_contacts>
          <surface>
            <contact>
              <ode/>
            </contact>
            <bounce/>
            <friction>
              <torsional>
                <ode/>
              </torsional>
              <ode/>
            </friction>
          </surface>
        </collision>
        <visual name='body_visual'>
          <pose>0 0 0 0 -0 0</pose>
          <geometry>
            <mesh>
              <scale>1 1 1</scale>
              <uri>model://meshes/body.STL</uri>
            </mesh>
          </geometry>
        </visual>
        <self_collide>0</self_collide>
        <enable_wind>0</enable_wind>
        <kinematic>0</kinematic>
      </link>
      <link name='bro'>
        <pose>-0.101 -0.0615 -0.024 1.28235 0.269455 -3.09986</pose>
        <inertial>
          <pose>0.115 -0 -0 0 -0 0</pose>
          <mass>0.0117925</mass>
          <inertia>
            <ixx>9.65368e-08</ixx>
            <ixy>4.10647e-12</ixy>
            <ixz>1.05145e-19</ixz>
            <iyy>5.42742e-05</iyy>
            <iyz>2.71051e-20</iyz>
            <izz>5.42722e-05</izz>
          </inertia>
        </inertial>
        <collision name='bro_collision'>
          <pose>0 0 0 0 -0 0</pose>
          <geometry>
            <mesh>
              <scale>1 1 1</scale>
              <uri>model://meshes/linkageOut.STL</uri>
            </mesh>
          </geometry>
          <max_contacts>10</max_contacts>
          <surface>
            <contact>
              <ode/>
            </contact>
            <bounce/>
            <friction>
              <torsional>
                <ode/>
              </torsional>
              <ode/>
            </friction>
          </surface>
        </collision>
        <visual name='bro_visual'>
          <pose>0 0 0 0 -0 0</pose>
          <geometry>
            <mesh>
              <scale>1 1 1</scale>
              <uri>model://meshes/linkageOut.STL</uri>
            </mesh>
          </geometry>
        </visual>
        <self_collide>0</self_collide>
        <enable_wind>0</enable_wind>
        <kinematic>0</kinematic>
      </link>
      <link name='backAxle'>
        <pose>-0.322508 -0.07075 -0.085227 0.267288 -0 1.5708</pose>
        <inertial>
          <pose>0.07075 0.019868 0.013586 0 -0 0</pose>
          <mass>0.0969889</mass>
          <inertia>
            <ixx>3.59997e-05</ixx>
            <ixy>3.0828e-11</ixy>
            <ixz>-2.58754e-11</ixz>
            <iyy>0.00045052</iyy>
            <iyz>9.38007e-07</iyz>
            <izz>0.00042565</izz>
          </inertia>
        </inertial>
        <collision name='backAxle_collision'>
          <pose>0 0 0 0 -0 0</pose>
          <geometry>
            <mesh>
              <scale>1 1 1</scale>
              <uri>model://meshes/axleRear.STL</uri>
            </mesh>
          </geometry>
          <max_contacts>10</max_contacts>
          <surface>
            <contact>
              <ode/>
            </contact>
            <bounce/>
            <friction>
              <torsional>
                <ode/>
              </torsional>
              <ode/>
            </friction>
          </surface>
        </collision>
        <visual name='backAxle_visual'>
          <pose>0 0 0 0 -0 0</pose>
          <geometry>
            <mesh>
              <scale>1 1 1</scale>
              <uri>model://meshes/axleRear.STL</uri>
            </mesh>
          </geometry>
        </visual>
        <self_collide>0</self_collide>
        <enable_wind>0</enable_wind>
        <kinematic>0</kinematic>
      </link>
      <link name='bli'>
        <pose>-0.315871 0.016 -0.013949 -0.604825 -0.143825 0.148221</pose>
        <inertial>
          <pose>0.0975 0 -0 0 -0 0</pose>
          <mass>0.0200332</mass>
          <inertia>
            <ixx>8.24621e-08</ixx>
            <ixy>2.3168e-12</ixy>
            <ixz>1.29699e-19</ixz>
            <iyy>3.34708e-05</iyy>
            <iyz>-3.30343e-20</iyz>
            <izz>3.34688e-05</izz>
          </inertia>
        </inertial>
        <collision name='bli_collision'>
          <pose>0 0 0 0 -0 0</pose>
          <geometry>
            <mesh>
              <scale>1 1 1</scale>
              <uri>model://meshes/linkageIn.STL</uri>
            </mesh>
          </geometry>
          <max_contacts>10</max_contacts>
          <surface>
            <contact>
              <ode/>
            </contact>
            <bounce/>
            <friction>
              <torsional>
                <ode/>
              </torsional>
              <ode/>
            </friction>
          </surface>
        </collision>
        <visual name='bli_visual'>
          <pose>0 0 0 0 -0 0</pose>
          <geometry>
            <mesh>
              <scale>1 1 1</scale>
              <uri>model://meshes/linkageIn.STL</uri>
            </mesh>
          </geometry>
        </visual>
        <self_collide>0</self_collide>
        <enable_wind>0</enable_wind>
        <kinematic>0</kinematic>
      </link>
      <link name='blo'>
        <pose>-0.322508 0.07075 -0.085227 2.55732 -0.269455 -0.041735</pose>
        <inertial>
          <pose>0.115 0 0 0 -0 0</pose>
          <mass>0.0117925</mass>
          <inertia>
            <ixx>9.65368e-08</ixx>
            <ixy>-4.10647e-12</ixy>
            <ixz>2.98276e-19</ixz>
            <iyy>5.42742e-05</iyy>
            <iyz>-6.94567e-20</iyz>
            <izz>5.42722e-05</izz>
          </inertia>
        </inertial>
        <collision name='blo_collision'>
          <pose>0 0 0 0 -0 0</pose>
          <geometry>
            <mesh>
              <scale>1 1 1</scale>
              <uri>model://meshes/linkageOut.STL</uri>
            </mesh>
          </geometry>
          <max_contacts>10</max_contacts>
          <surface>
            <contact>
              <ode/>
            </contact>
            <bounce/>
            <friction>
              <torsional>
                <ode/>
              </torsional>
              <ode/>
            </friction>
          </surface>
        </collision>
        <visual name='blo_visual'>
          <pose>0 0 0 0 -0 0</pose>
          <geometry>
            <mesh>
              <scale>1 1 1</scale>
              <uri>model://meshes/linkageOut.STL</uri>
            </mesh>
          </geometry>
        </visual>
        <self_collide>0</self_collide>
        <enable_wind>0</enable_wind>
        <kinematic>0</kinematic>
      </link>
      <link name='blslower'>
        <pose>-0.318186 0.092 -0.068785 -0.568218 -0.618473 -0.161762</pose>
        <inertial>
          <pose>0.016589 -0 0 0 -0 0</pose>
          <mass>0.0112311</mass>
          <inertia>
            <ixx>1.19839e-06</ixx>
            <ixy>-7.365e-14</ixy>
            <ixz>-1.39475e-14</ixz>
            <iyy>9.62721e-07</iyy>
            <iyz>1.3652e-15</iyz>
            <izz>9.62722e-07</izz>
          </inertia>
        </inertial>
        <collision name='blslower_collision'>
          <pose>0 0 0 0 -0 0</pose>
          <geometry>
            <mesh>
              <scale>1 1 1</scale>
              <uri>model://meshes/springPart.STL</uri>
            </mesh>
          </geometry>
          <max_contacts>10</max_contacts>
          <surface>
            <contact>
              <ode/>
            </contact>
            <bounce/>
            <friction>
              <torsional>
                <ode/>
              </torsional>
              <ode/>
            </friction>
          </surface>
        </collision>
        <visual name='blslower_visual'>
          <pose>0 0 0 0 -0 0</pose>
          <geometry>
            <mesh>
              <scale>1 1 1</scale>
              <uri>model://meshes/springPart.STL</uri>
            </mesh>
          </geometry>
        </visual>
        <self_collide>0</self_collide>
        <enable_wind>0</enable_wind>
        <kinematic>0</kinematic>
      </link>
      <link name='blsupper'>
        <pose>-0.1895 0.071 0.024 2.41118 0.618473 2.97983</pose>
        <inertial>
          <pose>0.016589 -0 0 0 -0 0</pose>
          <mass>0.0112311</mass>
          <inertia>
            <ixx>1.19839e-06</ixx>
            <ixy>-4.34583e-14</ixy>
            <ixz>-1.88149e-14</ixz>
            <iyy>9.62721e-07</iyy>
            <iyz>1.08668e-15</iyz>
            <izz>9.62722e-07</izz>
          </inertia>
        </inertial>
        <collision name='blsupper_collision'>
          <pose>0 0 0 0 -0 0</pose>
          <geometry>
            <mesh>
              <scale>1 1 1</scale>
              <uri>model://meshes/springPart.STL</uri>
            </mesh>
          </geometry>
          <max_contacts>10</max_contacts>
          <surface>
            <contact>
              <ode/>
            </contact>
            <bounce/>
            <friction>
              <torsional>
                <ode/>
              </torsional>
              <ode/>
            </friction>
          </surface>
        </collision>
        <visual name='blsupper_visual'>
          <pose>0 0 0 0 -0 0</pose>
          <geometry>
            <mesh>
              <scale>1 1 1</scale>
              <uri>model://meshes/springPart.STL</uri>
            </mesh>
          </geometry>
        </visual>
        <self_collide>0</self_collide>
        <enable_wind>0</enable_wind>
        <kinematic>0</kinematic>
      </link>
      <link name='blwheel'>
        <pose>-0.342683 0.115 -0.074 -2.8743 -0 1.5708</pose>
        <inertial>
          <pose>0.059171 0 0 0 -0 0</pose>
          <mass>0.19539</mass>
          <inertia>
            <ixx>6.03364e-05</ixx>
            <ixy>3.16416e-20</ixy>
            <ixz>-2.02141e-21</ixz>
            <iyy>0.000215224</iyy>
            <iyz>6.77626e-21</iyz>
            <izz>0.000212705</izz>
          </inertia>
        </inertial>
        <collision name='blwheel_collision'>
          <pose>0 0 0 0 -0 0</pose>
          <geometry>
            <mesh>
              <scale>1 1 1</scale>
              <uri>model://meshes/wheelHub.STL</uri>
            </mesh>
          </geometry>
          <max_contacts>10</max_contacts>
          <surface>
            <contact>
              <ode/>
            </contact>
            <bounce/>
            <friction>
              <torsional>
                <ode/>
              </torsional>
              <ode/>
            </friction>
          </surface>
        </collision>
        <visual name='blwheel_visual'>
          <pose>0 0 0 0 -0 0</pose>
          <geometry>
            <mesh>
              <scale>1 1 1</scale>
              <uri>model://meshes/wheelHub.STL</uri>
            </mesh>
          </geometry>
        </visual>
        <self_collide>0</self_collide>
        <enable_wind>0</enable_wind>
        <kinematic>0</kinematic>
      </link>
      <link name='bri'>
        <pose>-0.315871 -0.016 -0.013949 1.44194 -0.143825 -0.148221</pose>
        <inertial>
          <pose>0.0975 0 0 0 -0 0</pose>
          <mass>0.0200332</mass>
          <inertia>
            <ixx>8.24621e-08</ixx>
            <ixy>-2.3168e-12</ixy>
            <ixz>-2.12659e-19</ixz>
            <iyy>3.34708e-05</iyy>
            <iyz>5.97158e-20</iyz>
            <izz>3.34688e-05</izz>
          </inertia>
        </inertial>
        <collision name='bri_collision'>
          <pose>0 0 0 0 -0 0</pose>
          <geometry>
            <mesh>
              <scale>1 1 1</scale>
              <uri>model://meshes/linkageIn.STL</uri>
            </mesh>
          </geometry>
          <max_contacts>10</max_contacts>
          <surface>
            <contact>
              <ode/>
            </contact>
            <bounce/>
            <friction>
              <torsional>
                <ode/>
              </torsional>
              <ode/>
            </friction>
          </surface>
        </collision>
        <visual name='bri_visual'>
          <pose>0 0 0 0 -0 0</pose>
          <geometry>
            <mesh>
              <scale>1 1 1</scale>
              <uri>model://meshes/linkageIn.STL</uri>
            </mesh>
          </geometry>
        </visual>
        <self_collide>0</self_collide>
        <enable_wind>0</enable_wind>
        <kinematic>0</kinematic>
      </link>
      <link name='brslower'>
        <pose>-0.318186 -0.092 -0.068785 -0.210766 -0.618473 0.161762</pose>
        <inertial>
          <pose>0.016589 0 0 0 -0 0</pose>
          <mass>0.0112311</mass>
          <inertia>
            <ixx>1.19839e-06</ixx>
            <ixy>6.27133e-15</ixy>
            <ixz>-2.09143e-14</ixz>
            <iyy>9.62721e-07</iyy>
            <iyz>-1.74313e-16</iyz>
            <izz>9.62722e-07</izz>
          </inertia>
        </inertial>
        <collision name='brslower_collision'>
          <pose>0 0 0 0 -0 0</pose>
          <geometry>
            <mesh>
              <scale>1 1 1</scale>
              <uri>model://meshes/springPart.STL</uri>
            </mesh>
          </geometry>
          <max_contacts>10</max_contacts>
          <surface>
            <contact>
              <ode/>
            </contact>
            <bounce/>
            <friction>
              <torsional>
                <ode/>
              </torsional>
              <ode/>
            </friction>
          </surface>
        </collision>
        <visual name='brslower_visual'>
          <pose>0 0 0 0 -0 0</pose>
          <geometry>
            <mesh>
              <scale>1 1 1</scale>
              <uri>model://meshes/springPart.STL</uri>
            </mesh>
          </geometry>
        </visual>
        <self_collide>0</self_collide>
        <enable_wind>0</enable_wind>
        <kinematic>0</kinematic>
      </link>
      <link name='brsupper'>
        <pose>-0.1895 -0.071 0.024 2.05373 0.618473 -2.97983</pose>
        <inertial>
          <pose>0.016589 -0 0 0 -0 0</pose>
          <mass>0.0112311</mass>
          <inertia>
            <ixx>1.19839e-06</ixx>
            <ixy>-9.65399e-14</ixy>
            <ixz>-4.33935e-15</ixz>
            <iyy>9.62721e-07</iyy>
            <iyz>5.56748e-16</iyz>
            <izz>9.62722e-07</izz>
          </inertia>
        </inertial>
        <collision name='brsupper_collision'>
          <pose>0 0 0 0 -0 0</pose>
          <geometry>
            <mesh>
              <scale>1 1 1</scale>
              <uri>model://meshes/springPart.STL</uri>
            </mesh>
          </geometry>
          <max_contacts>10</max_contacts>
          <surface>
            <contact>
              <ode/>
            </contact>
            <bounce/>
            <friction>
              <torsional>
                <ode/>
              </torsional>
              <ode/>
            </friction>
          </surface>
        </collision>
        <visual name='brsupper_visual'>
          <pose>0 0 0 0 -0 0</pose>
          <geometry>
            <mesh>
              <scale>1 1 1</scale>
              <uri>model://meshes/springPart.STL</uri>
            </mesh>
          </geometry>
        </visual>
        <self_collide>0</self_collide>
        <enable_wind>0</enable_wind>
        <kinematic>0</kinematic>
      </link>
      <link name='brwheel'>
        <pose>-0.342683 -0.115 -0.074 2.8743 -0 -1.5708</pose>
        <inertial>
          <pose>0.059171 -0 0 0 -0 0</pose>
          <mass>0.19539</mass>
          <inertia>
            <ixx>6.03364e-05</ixx>
            <ixy>8.21409e-21</ixy>
            <ixz>-4.18157e-21</ixz>
            <iyy>0.000215224</iyy>
            <iyz>1.35525e-20</iyz>
            <izz>0.000212705</izz>
          </inertia>
        </inertial>
        <collision name='brwheel_collision'>
          <pose>0 0 0 0 -0 0</pose>
          <geometry>
            <mesh>
              <scale>1 1 1</scale>
              <uri>model://meshes/wheelHub.STL</uri>
            </mesh>
          </geometry>
          <max_contacts>10</max_contacts>
          <surface>
            <contact>
              <ode/>
            </contact>
            <bounce/>
            <friction>
              <torsional>
                <ode/>
              </torsional>
              <ode/>
            </friction>
          </surface>
        </collision>
        <visual name='brwheel_visual'>
          <pose>0 0 0 0 -0 0</pose>
          <geometry>
            <mesh>
              <scale>1 1 1</scale>
              <uri>model://meshes/wheelHub.STL</uri>
            </mesh>
          </geometry>
        </visual>
        <self_collide>0</self_collide>
        <enable_wind>0</enable_wind>
        <kinematic>0</kinematic>
      </link>
      <link name='fro'>
        <pose>0.101 -0.0615 -0.024 2.1962 0.26945 -0.041735</pose>
        <inertial>
          <pose>0.115 -0 0 0 -0 0</pose>
          <mass>0.0117925</mass>
          <inertia>
            <ixx>9.65368e-08</ixx>
            <ixy>-4.10647e-12</ixy>
            <ixz>-5.41898e-20</ixz>
            <iyy>5.42742e-05</iyy>
            <iyz>-2.03288e-20</iyz>
            <izz>5.42722e-05</izz>
          </inertia>
        </inertial>
        <collision name='fro_collision'>
          <pose>0 0 0 0 -0 0</pose>
          <geometry>
            <mesh>
              <scale>1 1 1</scale>
              <uri>model://meshes/linkageOut.STL</uri>
            </mesh>
          </geometry>
          <max_contacts>10</max_contacts>
          <surface>
            <contact>
              <ode/>
            </contact>
            <bounce/>
            <friction>
              <torsional>
                <ode/>
              </torsional>
              <ode/>
            </friction>
          </surface>
        </collision>
        <visual name='fro_visual'>
          <pose>0 0 0 0 -0 0</pose>
          <geometry>
            <mesh>
              <scale>1 1 1</scale>
              <uri>model://meshes/linkageOut.STL</uri>
            </mesh>
          </geometry>
        </visual>
        <self_collide>0</self_collide>
        <enable_wind>0</enable_wind>
        <kinematic>0</kinematic>
      </link>
      <link name='frontAxle'>
        <pose>0.322508 -0.07075 -0.085226 -0.267269 -2.4e-05 1.57078</pose>
        <inertial>
          <pose>0.07075 -0.019868 0.013586 0 -0 0</pose>
          <mass>0.0969889</mass>
          <inertia>
            <ixx>3.59997e-05</ixx>
            <ixy>3.0828e-11</ixy>
            <ixz>2.58754e-11</ixz>
            <iyy>0.00045052</iyy>
            <iyz>-9.38007e-07</iyz>
            <izz>0.00042565</izz>
          </inertia>
        </inertial>
        <collision name='frontAxle_collision'>
          <pose>0 0 0 0 -0 0</pose>
          <geometry>
            <mesh>
              <scale>1 1 1</scale>
              <uri>model://meshes/axleFront.STL</uri>
            </mesh>
          </geometry>
          <max_contacts>10</max_contacts>
          <surface>
            <contact>
              <ode/>
            </contact>
            <bounce/>
            <friction>
              <torsional>
                <ode/>
              </torsional>
              <ode/>
            </friction>
          </surface>
        </collision>
        <visual name='frontAxle_visual'>
          <pose>0 0 0 0 -0 0</pose>
          <geometry>
            <mesh>
              <scale>1 1 1</scale>
              <uri>model://meshes/axleFront.STL</uri>
            </mesh>
          </geometry>
        </visual>
        <self_collide>0</self_collide>
        <enable_wind>0</enable_wind>
        <kinematic>0</kinematic>
      </link>
      <link name='fli'>
        <pose>0.315873 0.015998 -0.013946 0.904649 -0.143848 2.99336</pose>
        <inertial>
          <pose>0.0975 0 -0 0 -0 0</pose>
          <mass>0.0200332</mass>
          <inertia>
            <ixx>8.24621e-08</ixx>
            <ixy>2.3168e-12</ixy>
            <ixz>-1.57474e-19</ixz>
            <iyy>3.34708e-05</iyy>
            <iyz>-1.18585e-20</iyz>
            <izz>3.34688e-05</izz>
          </inertia>
        </inertial>
        <collision name='fli_collision'>
          <pose>0 0 0 0 -0 0</pose>
          <geometry>
            <mesh>
              <scale>1 1 1</scale>
              <uri>model://meshes/linkageIn.STL</uri>
            </mesh>
          </geometry>
          <max_contacts>10</max_contacts>
          <surface>
            <contact>
              <ode/>
            </contact>
            <bounce/>
            <friction>
              <torsional>
                <ode/>
              </torsional>
              <ode/>
            </friction>
          </surface>
        </collision>
        <visual name='fli_visual'>
          <pose>0 0 0 0 -0 0</pose>
          <geometry>
            <mesh>
              <scale>1 1 1</scale>
              <uri>model://meshes/linkageIn.STL</uri>
            </mesh>
          </geometry>
        </visual>
        <self_collide>0</self_collide>
        <enable_wind>0</enable_wind>
        <kinematic>0</kinematic>
      </link>
      <link name='flo'>
        <pose>0.32251 0.07075 -0.085223 0.756048 -0.269473 -3.09986</pose>
        <inertial>
          <pose>0.115 -0 -0 0 -0 0</pose>
          <mass>0.0117925</mass>
          <inertia>
            <ixx>9.65368e-08</ixx>
            <ixy>4.10647e-12</ixy>
            <ixz>-1.48398e-19</ixz>
            <iyy>5.42742e-05</iyy>
            <iyz>5.75982e-20</iyz>
            <izz>5.42722e-05</izz>
          </inertia>
        </inertial>
        <collision name='flo_collision'>
          <pose>0 0 0 0 -0 0</pose>
          <geometry>
            <mesh>
              <scale>1 1 1</scale>
              <uri>model://meshes/linkageOut.STL</uri>
            </mesh>
          </geometry>
          <max_contacts>10</max_contacts>
          <surface>
            <contact>
              <ode/>
            </contact>
            <bounce/>
            <friction>
              <torsional>
                <ode/>
              </torsional>
              <ode/>
            </friction>
          </surface>
        </collision>
        <visual name='flo_visual'>
          <pose>0 0 0 0 -0 0</pose>
          <geometry>
            <mesh>
              <scale>1 1 1</scale>
              <uri>model://meshes/linkageOut.STL</uri>
            </mesh>
          </geometry>
        </visual>
        <self_collide>0</self_collide>
        <enable_wind>0</enable_wind>
        <kinematic>0</kinematic>
      </link>
      <link name='flslower'>
        <pose>0.318189 0.092 -0.06878 -1.43248 -0.618488 -2.97982</pose>
        <inertial>
          <pose>0.016589 -0 0 0 -0 0</pose>
          <mass>0.0112311</mass>
          <inertia>
            <ixx>1.19839e-06</ixx>
            <ixy>-9.03931e-14</ixy>
            <ixz>-8.40562e-15</ixz>
            <iyy>9.62721e-07</iyy>
            <iyz>1.00979e-15</iyz>
            <izz>9.62722e-07</izz>
          </inertia>
        </inertial>
        <collision name='flslower_collision'>
          <pose>0 0 0 0 -0 0</pose>
          <geometry>
            <mesh>
              <scale>1 1 1</scale>
              <uri>model://meshes/springPart.STL</uri>
            </mesh>
          </geometry>
          <max_contacts>10</max_contacts>
          <surface>
            <contact>
              <ode/>
            </contact>
            <bounce/>
            <friction>
              <torsional>
                <ode/>
              </torsional>
              <ode/>
            </friction>
          </surface>
        </collision>
        <visual name='flslower_visual'>
          <pose>0 0 0 0 -0 0</pose>
          <geometry>
            <mesh>
              <scale>1 1 1</scale>
              <uri>model://meshes/springPart.STL</uri>
            </mesh>
          </geometry>
        </visual>
        <self_collide>0</self_collide>
        <enable_wind>0</enable_wind>
        <kinematic>0</kinematic>
      </link>
      <link name='flsupper'>
        <pose>0.189504 0.070999 0.024007 2.4484 0.618488 0.161768</pose>
        <inertial>
          <pose>0.016589 -0 0 0 -0 0</pose>
          <mass>0.0112311</mass>
          <inertia>
            <ixx>1.19839e-06</ixx>
            <ixy>-8.12639e-14</ixy>
            <ixz>-1.18884e-14</ixz>
            <iyy>9.62721e-07</iyy>
            <iyz>1.28395e-15</iyz>
            <izz>9.62722e-07</izz>
          </inertia>
        </inertial>
        <collision name='flsupper_collision'>
          <pose>0 0 0 0 -0 0</pose>
          <geometry>
            <mesh>
              <scale>1 1 1</scale>
              <uri>model://meshes/springPart.STL</uri>
            </mesh>
          </geometry>
          <max_contacts>10</max_contacts>
          <surface>
            <contact>
              <ode/>
            </contact>
            <bounce/>
            <friction>
              <torsional>
                <ode/>
              </torsional>
              <ode/>
            </friction>
          </surface>
        </collision>
        <visual name='flsupper_visual'>
          <pose>0 0 0 0 -0 0</pose>
          <geometry>
            <mesh>
              <scale>1 1 1</scale>
              <uri>model://meshes/springPart.STL</uri>
            </mesh>
          </geometry>
        </visual>
        <self_collide>0</self_collide>
        <enable_wind>0</enable_wind>
        <kinematic>0</kinematic>
      </link>
      <link name='flwheel'>
        <pose>0.342686 0.114999 -0.073995 2.87432 -2.4e-05 1.57078</pose>
        <inertial>
          <pose>0.059171 0 0 0 -0 0</pose>
          <mass>0.19539</mass>
          <inertia>
            <ixx>6.03364e-05</ixx>
            <ixy>7.91021e-21</ixy>
            <ixz>4.51343e-21</ixz>
            <iyy>0.000215224</iyy>
            <iyz>2.37169e-20</iyz>
            <izz>0.000212705</izz>
          </inertia>
        </inertial>
        <collision name='flwheel_collision'>
          <pose>0 0 0 0 -0 0</pose>
          <geometry>
            <mesh>
              <scale>1 1 1</scale>
              <uri>model://meshes/wheelHub.STL</uri>
            </mesh>
          </geometry>
          <max_contacts>10</max_contacts>
          <surface>
            <contact>
              <ode/>
            </contact>
            <bounce/>
            <friction>
              <torsional>
                <ode/>
              </torsional>
              <ode/>
            </friction>
          </surface>
        </collision>
        <visual name='flwheel_visual'>
          <pose>0 0 0 0 -0 0</pose>
          <geometry>
            <mesh>
              <scale>1 1 1</scale>
              <uri>model://meshes/wheelHub.STL</uri>
            </mesh>
          </geometry>
        </visual>
        <self_collide>0</self_collide>
        <enable_wind>0</enable_wind>
        <kinematic>0</kinematic>
      </link>
      <link name='fri'>
        <pose>0.315873 -0.016002 -0.013947 0.861564 -0.143841 -2.99338</pose>
        <inertial>
          <pose>0.0975 0 -0 0 -0 0</pose>
          <mass>0.0200332</mass>
          <inertia>
            <ixx>8.24621e-08</ixx>
            <ixy>2.3168e-12</ixy>
            <ixz>6.46458e-20</ixz>
            <iyy>3.34708e-05</iyy>
            <iyz>-2.20229e-20</iyz>
            <izz>3.34688e-05</izz>
          </inertia>
        </inertial>
        <collision name='fri_collision'>
          <pose>0 0 0 0 -0 0</pose>
          <geometry>
            <mesh>
              <scale>1 1 1</scale>
              <uri>model://meshes/linkageIn.STL</uri>
            </mesh>
          </geometry>
          <max_contacts>10</max_contacts>
          <surface>
            <contact>
              <ode/>
            </contact>
            <bounce/>
            <friction>
              <torsional>
                <ode/>
              </torsional>
              <ode/>
            </friction>
          </surface>
        </collision>
        <visual name='fri_visual'>
          <pose>0 0 0 0 -0 0</pose>
          <geometry>
            <mesh>
              <scale>1 1 1</scale>
              <uri>model://meshes/linkageIn.STL</uri>
            </mesh>
          </geometry>
        </visual>
        <self_collide>0</self_collide>
        <enable_wind>0</enable_wind>
        <kinematic>0</kinematic>
      </link>
      <link name='frslower'>
        <pose>0.318186 -0.092 -0.068784 -0.708805 -0.618496 2.97983</pose>
        <inertial>
          <pose>0.016589 -0 0 0 -0 0</pose>
          <mass>0.0112311</mass>
          <inertia>
            <ixx>1.19839e-06</ixx>
            <ixy>-8.21246e-14</ixy>
            <ixz>-1.16186e-14</ixz>
            <iyy>9.62721e-07</iyy>
            <iyz>1.2681e-15</iyz>
            <izz>9.62722e-07</izz>
          </inertia>
        </inertial>
        <collision name='frslower_collision'>
          <pose>0 0 0 0 -0 0</pose>
          <geometry>
            <mesh>
              <scale>1 1 1</scale>
              <uri>model://meshes/springPart.STL</uri>
            </mesh>
          </geometry>
          <max_contacts>10</max_contacts>
          <surface>
            <contact>
              <ode/>
            </contact>
            <bounce/>
            <friction>
              <torsional>
                <ode/>
              </torsional>
              <ode/>
            </friction>
          </surface>
        </collision>
        <visual name='frslower_visual'>
          <pose>0 0 0 0 -0 0</pose>
          <geometry>
            <mesh>
              <scale>1 1 1</scale>
              <uri>model://meshes/springPart.STL</uri>
            </mesh>
          </geometry>
        </visual>
        <self_collide>0</self_collide>
        <enable_wind>0</enable_wind>
        <kinematic>0</kinematic>
      </link>
      <link name='frsupper'>
        <pose>0.189502 -0.071001 0.024004 1.72472 0.618496 -0.161761</pose>
        <inertial>
          <pose>0.016589 -0 0 0 -0 0</pose>
          <mass>0.0112311</mass>
          <inertia>
            <ixx>1.19839e-06</ixx>
            <ixy>-8.97667e-14</ixy>
            <ixz>-8.70313e-15</ixz>
            <iyy>9.62721e-07</iyy>
            <iyz>1.03829e-15</iyz>
            <izz>9.62722e-07</izz>
          </inertia>
        </inertial>
        <collision name='frsupper_collision'>
          <pose>0 0 0 0 -0 0</pose>
          <geometry>
            <mesh>
              <scale>1 1 1</scale>
              <uri>model://meshes/springPart.STL</uri>
            </mesh>
          </geometry>
          <max_contacts>10</max_contacts>
          <surface>
            <contact>
              <ode/>
            </contact>
            <bounce/>
            <friction>
              <torsional>
                <ode/>
              </torsional>
              <ode/>
            </friction>
          </surface>
        </collision>
        <visual name='frsupper_visual'>
          <pose>0 0 0 0 -0 0</pose>
          <geometry>
            <mesh>
              <scale>1 1 1</scale>
              <uri>model://meshes/springPart.STL</uri>
            </mesh>
          </geometry>
        </visual>
        <self_collide>0</self_collide>
        <enable_wind>0</enable_wind>
        <kinematic>0</kinematic>
      </link>
      <link name='frwheel'>
        <pose>0.342683 -0.115001 -0.074 0.267269 2.4e-05 -1.57081</pose>
        <inertial>
          <pose>0.059171 0 -0 0 -0 0</pose>
          <mass>0.19539</mass>
          <inertia>
            <ixx>6.03364e-05</ixx>
            <ixy>-7.33769e-21</ixy>
            <ixz>2.87017e-21</ixz>
            <iyy>0.000215224</iyy>
            <iyz>-3.38813e-21</iyz>
            <izz>0.000212705</izz>
          </inertia>
        </inertial>
        <collision name='frwheel_collision'>
          <pose>0 0 0 0 -0 0</pose>
          <geometry>
            <mesh>
              <scale>1 1 1</scale>
              <uri>model://meshes/wheelHub.STL</uri>
            </mesh>
          </geometry>
          <max_contacts>10</max_contacts>
          <surface>
            <contact>
              <ode/>
            </contact>
            <bounce/>
            <friction>
              <torsional>
                <ode/>
              </torsional>
              <ode/>
            </friction>
          </surface>
        </collision>
        <visual name='frwheel_visual'>
          <pose>0 0 0 0 -0 0</pose>
          <geometry>
            <mesh>
              <scale>1 1 1</scale>
              <uri>model://meshes/wheelHub.STL</uri>
            </mesh>
          </geometry>
        </visual>
        <self_collide>0</self_collide>
        <enable_wind>0</enable_wind>
        <kinematic>0</kinematic>
      </link>
      <link name='fltire'>
        <pose>0.342686 0.134999 -0.073994 -1.4358 -2.4e-05 1.57078</pose>
        <inertial>
          <pose>0.045 0 0 0 -0 0</pose>
          <mass>2.65072</mass>
          <inertia>
            <ixx>0.0140819</ixx>
            <ixy>-1.63996e-19</ixy>
            <ixz>-5.51633e-19</ixz>
            <iyy>0.00883021</iyy>
            <iyz>-1.0842e-19</iyz>
            <izz>0.00883021</izz>
          </inertia>
        </inertial>
        <collision name='fltire_collision'>
          <pose>0.045 0 0 3.14159 1.57079 3.14159</pose>
          <geometry>
            <cylinder>
              <radius>0.1</radius>
              <length>0.09</length>
            </cylinder>
          </geometry>
          <max_contacts>10</max_contacts>
          <surface>
            <contact>
              <ode/>
            </contact>
            <bounce/>
            <friction>
              <torsional>
                <ode/>
              </torsional>
              <ode/>
            </friction>
          </surface>
        </collision>
        <visual name='fltire_visual'>
          <pose>0.045 0 0 3.14159 1.57079 3.14159</pose>
          <geometry>
            <cylinder>
              <radius>0.1</radius>
              <length>0.09</length>
            </cylinder>
          </geometry>
        </visual>
        <self_collide>0</self_collide>
        <enable_wind>0</enable_wind>
        <kinematic>0</kinematic>
      </link>
      <link name='frtire'>
        <pose>0.342682 -0.225001 -0.074003 -1.07467 -2.4e-05 1.57078</pose>
        <inertial>
          <pose>0.045 -0 0 0 -0 0</pose>
          <mass>2.65072</mass>
          <inertia>
            <ixx>0.0140819</ixx>
            <ixy>6.05221e-19</ixy>
            <ixz>2.56811e-19</ixz>
            <iyy>0.00883021</iyy>
            <iyz>-8.67362e-19</iyz>
            <izz>0.00883021</izz>
          </inertia>
        </inertial>
        <collision name='frtire_collision'>
          <pose>0.045 0 0 3.14159 1.57079 3.14159</pose>
          <geometry>
            <cylinder>
              <radius>0.1</radius>
              <length>0.09</length>
            </cylinder>
          </geometry>
          <max_contacts>10</max_contacts>
          <surface>
            <contact>
              <ode/>
            </contact>
            <bounce/>
            <friction>
              <torsional>
                <ode/>
              </torsional>
              <ode/>
            </friction>
          </surface>
        </collision>
        <visual name='frtire_visual'>
          <pose>0.045 0 0 3.14159 1.57079 3.14159</pose>
          <geometry>
            <cylinder>
              <radius>0.1</radius>
              <length>0.09</length>
            </cylinder>
          </geometry>
        </visual>
        <self_collide>0</self_collide>
        <enable_wind>0</enable_wind>
        <kinematic>0</kinematic>
      </link>
      <link name='bltire'>
        <pose>-0.342683 0.135 -0.074 -2.31924 -0 1.5708</pose>
        <inertial>
          <pose>0.045 0 -0 0 -0 0</pose>
          <mass>2.65072</mass>
          <inertia>
            <ixx>0.0140819</ixx>
            <ixy>-2.23921e-19</ixy>
            <ixz>-3.27444e-19</ixz>
            <iyy>0.00883021</iyy>
            <iyz>2.1684e-18</iyz>
            <izz>0.00883021</izz>
          </inertia>
        </inertial>
        <collision name='bltire_collision'>
          <pose>0.045 0 0 3.14159 1.57079 3.14159</pose>
          <geometry>
            <cylinder>
              <radius>0.1</radius>
              <length>0.09</length>
            </cylinder>
          </geometry>
          <max_contacts>10</max_contacts>
          <surface>
            <contact>
              <ode/>
            </contact>
            <bounce/>
            <friction>
              <torsional>
                <ode/>
              </torsional>
              <ode/>
            </friction>
          </surface>
        </collision>
        <visual name='bltire_visual'>
          <pose>0.045 0 0 3.14159 1.57079 3.14159</pose>
          <geometry>
            <cylinder>
              <radius>0.1</radius>
              <length>0.09</length>
            </cylinder>
          </geometry>
        </visual>
        <self_collide>0</self_collide>
        <enable_wind>0</enable_wind>
        <kinematic>0</kinematic>
      </link>
      <link name='brtire'>
        <pose>-0.342683 -0.225 -0.074 -2.87457 -0 1.5708</pose>
        <inertial>
          <pose>0.045 0 0 0 -0 0</pose>
          <mass>2.65072</mass>
          <inertia>
            <ixx>0.0140819</ixx>
            <ixy>2.01201e-19</ixy>
            <ixz>-7.89159e-20</ixz>
            <iyy>0.00883021</iyy>
            <iyz>-4.33681e-19</iyz>
            <izz>0.00883021</izz>
          </inertia>
        </inertial>
        <collision name='brtire_collision'>
          <pose>0.045 0 0 3.14159 1.57079 3.14159</pose>
          <geometry>
            <cylinder>
              <radius>0.1</radius>
              <length>0.09</length>
            </cylinder>
          </geometry>
          <max_contacts>10</max_contacts>
          <surface>
            <contact>
              <ode/>
            </contact>
            <bounce/>
            <friction>
              <torsional>
                <ode/>
              </torsional>
              <ode/>
            </friction>
          </surface>
        </collision>
        <visual name='brtire_visual'>
          <pose>0.045 0 0 3.14159 1.57079 3.14159</pose>
          <geometry>
            <cylinder>
              <radius>0.1</radius>
              <length>0.09</length>
            </cylinder>
          </geometry>
        </visual>
        <self_collide>0</self_collide>
        <enable_wind>0</enable_wind>
        <kinematic>0</kinematic>
      </link>
      <link name='frontSteeringBar'>
        <pose>0.342686 0.114999 -0.073995 2.87432 -2.4e-05 1.57078</pose>
        <self_collide>0</self_collide>
        <inertial>
          <pose>0 0 0 0 -0 0</pose>
          <inertia>
            <ixx>1</ixx>
            <ixy>0</ixy>
            <ixz>0</ixz>
            <iyy>1</iyy>
            <iyz>0</iyz>
            <izz>1</izz>
          </inertia>
          <mass>1</mass>
        </inertial>
        <enable_wind>0</enable_wind>
        <kinematic>0</kinematic>
      </link>
      <link name='backSteeringBar'>
        <pose>-0.342686 0.114999 -0.073995 2.87432 -2.4e-05 1.57078</pose>
        <self_collide>0</self_collide>
        <inertial>
          <pose>0 0 0 0 -0 0</pose>
          <inertia>
            <ixx>1</ixx>
            <ixy>0</ixy>
            <ixz>0</ixz>
            <iyy>1</iyy>
            <iyz>0</iyz>
            <izz>1</izz>
          </inertia>
          <mass>1</mass>
        </inertial>
        <enable_wind>0</enable_wind>
        <kinematic>0</kinematic>
      </link>
      <joint name='frontSteeringRight' type='revolute'>
        <child>frwheel</child>
        <parent>frontSteeringBar</parent>
        <pose>0 0.2 0 0 -0 0</pose>
        <axis>
          <xyz>0 0 1</xyz>
          <limit>
            <lower>-3.14</lower>
            <upper>3.14</upper>
          </limit>
          <dynamics>
            <spring_reference>0</spring_reference>
            <spring_stiffness>0</spring_stiffness>
          </dynamics>
        </axis>
      </joint>
      <joint name='frontSteeringLeft' type='revolute'>
        <child>flwheel</child>
        <parent>frontSteeringBar</parent>
        <pose>0 0.2 0 0 -0 0</pose>
        <axis>
          <xyz>0 0 1</xyz>
          <limit>
            <lower>-3.14</lower>
            <upper>3.14</upper>
          </limit>
          <dynamics>
            <spring_reference>0</spring_reference>
            <spring_stiffness>0</spring_stiffness>
          </dynamics>
        </axis>
      </joint>
      <joint name='backSteeringRight' type='revolute'>
        <child>brwheel</child>
        <parent>backSteeringBar</parent>
        <pose>0 -0.2 0 0 -0 0</pose>
        <axis>
          <xyz>0 0 1</xyz>
          <limit>
            <lower>-3.14</lower>
            <upper>3.14</upper>
          </limit>
          <dynamics>
            <spring_reference>0</spring_reference>
            <spring_stiffness>0</spring_stiffness>
          </dynamics>
        </axis>
      </joint>
      <joint name='backSteeringLeft' type='revolute'>
        <child>blwheel</child>
        <parent>backSteeringBar</parent>
        <pose>0 -0.2 0 0 -0 0</pose>
        <axis>
          <xyz>0 0 1</xyz>
          <limit>
            <lower>-3.14</lower>
            <upper>3.14</upper>
          </limit>
          <dynamics>
            <spring_reference>0</spring_reference>
            <spring_stiffness>0</spring_stiffness>
          </dynamics>
        </axis>
      </joint>
      <joint name='body2bro' type='ball'>
        <child>bro</child>
        <parent>body</parent>
      </joint>
      <joint name='bro2axle' type='ball'>
        <child>backAxle</child>
        <parent>bro</parent>
      </joint>
      <joint name='axle2bli' type='ball'>
        <child>bli</child>
        <parent>backAxle</parent>
      </joint>
      <joint name='axle2blo' type='ball'>
        <child>blo</child>
        <parent>backAxle</parent>
      </joint>
      <joint name='axle2blslower' type='ball'>
        <child>blslower</child>
        <parent>backAxle</parent>
      </joint>
      <joint name='axle2blwheel' type='revolute'>
        <child>blwheel</child>
        <parent>backAxle</parent>
        <axis>
          <xyz expressed_in='__model__'>0.264117 0 0.964491</xyz>
          <limit>
            <lower>0</lower>
            <upper>0</upper>
            <effort>0</effort>
            <velocity>0</velocity>
          </limit>
          <dynamics>
            <spring_reference>0</spring_reference>
            <spring_stiffness>0</spring_stiffness>
          </dynamics>
        </axis>
      </joint>
      <joint name='blwheel2tire' type='revolute'>
        <child>bltire</child>
        <parent>blwheel</parent>
        <axis>
          <xyz expressed_in='__model__'>-0 1 0</xyz>
          <dynamics>
            <spring_reference>0</spring_reference>
            <spring_stiffness>0</spring_stiffness>
          </dynamics>
          <limit>
            <lower>-1e+16</lower>
            <upper>1e+16</upper>
          </limit>
        </axis>
      </joint>
      <joint name='axle2bri' type='ball'>
        <child>bri</child>
        <parent>backAxle</parent>
      </joint>
      <joint name='axle2brslower' type='ball'>
        <child>brslower</child>
        <parent>backAxle</parent>
      </joint>
      <joint name='axle2brwheel' type='revolute'>
        <child>brwheel</child>
        <parent>backAxle</parent>
        <axis>
          <xyz expressed_in='__model__'>0.264117 0 0.964491</xyz>
          <limit>
            <lower>0</lower>
            <upper>0</upper>
            <effort>0</effort>
            <velocity>0</velocity>
          </limit>
          <dynamics>
            <spring_reference>0</spring_reference>
            <spring_stiffness>0</spring_stiffness>
          </dynamics>
        </axis>
      </joint>
      <joint name='brwheel2tire' type='revolute'>
        <child>brtire</child>
        <parent>brwheel</parent>
        <axis>
          <xyz expressed_in='__model__'>-0 1 0</xyz>
          <limit>
            <lower>-1e+16</lower>
            <upper>1e+16</upper>
          </limit>
          <dynamics>
            <spring_reference>0</spring_reference>
            <spring_stiffness>0</spring_stiffness>
          </dynamics>
        </axis>
      </joint>
      <joint name='body2fro' type='ball'>
        <child>fro</child>
        <parent>body</parent>
      </joint>
      <joint name='fro2Axle' type='ball'>
        <child>frontAxle</child>
        <parent>fro</parent>
      </joint>
      <joint name='axle2fli' type='ball'>
        <child>fli</child>
        <parent>frontAxle</parent>
      </joint>
      <joint name='axle2flo' type='ball'>
        <child>flo</child>
        <parent>frontAxle</parent>
      </joint>
      <joint name='axle2flslower' type='ball'>
        <child>flslower</child>
        <parent>frontAxle</parent>
      </joint>
      <joint name='axle2flwheel' type='revolute'>
        <child>flwheel</child>
        <parent>frontAxle</parent>
        <axis>
          <xyz expressed_in='__model__'>-0.264098 -2e-05 0.964496</xyz>
          <limit>
            <lower>-0.5</lower>
            <upper>0.5</upper>
          </limit>
          <dynamics>
            <spring_reference>0</spring_reference>
            <spring_stiffness>0</spring_stiffness>
          </dynamics>
        </axis>
      </joint>
      <joint name='flwheel2tire' type='revolute'>
        <child>fltire</child>
        <parent>flwheel</parent>
        <axis>
          <xyz expressed_in='__model__'>1.3e-05 1 2.4e-05</xyz>
          <limit>
            <lower>-1e+16</lower>
            <upper>1e+16</upper>
          </limit>
          <dynamics>
            <spring_reference>0</spring_reference>
            <spring_stiffness>0</spring_stiffness>
          </dynamics>
        </axis>
      </joint>
      <joint name='axle2fri' type='ball'>
        <child>fri</child>
        <parent>frontAxle</parent>
      </joint>
      <joint name='axle2frslower' type='ball'>
        <child>frslower</child>
        <parent>frontAxle</parent>
      </joint>
      <joint name='axle2frwheel' type='revolute'>
        <child>frwheel</child>
        <parent>frontAxle</parent>
        <axis>
          <xyz expressed_in='__model__'>0.264098 2e-05 -0.964496</xyz>
          <limit>
            <lower>-0.5</lower>
            <upper>0.5</upper>
          </limit>
          <dynamics>
            <spring_reference>0</spring_reference>
            <spring_stiffness>0</spring_stiffness>
          </dynamics>
        </axis>
      </joint>
      <joint name='frwheel2tire' type='revolute'>
        <child>frtire</child>
        <parent>frwheel</parent>
        <axis>
          <xyz expressed_in='__model__'>1.3e-05 1 2.4e-05</xyz>
          <limit>
            <lower>-1e+16</lower>
            <upper>1e+16</upper>
          </limit>
          <dynamics>
            <spring_reference>0</spring_reference>
            <spring_stiffness>0</spring_stiffness>
          </dynamics>
        </axis>
      </joint>
      <joint name='brslower2upper' type='prismatic'>
        <child>brsupper</child>
        <parent>brslower</parent>
        <axis>
          <xyz expressed_in='__model__'>-0.804128 -0.131224 -0.579792</xyz>
          <limit>
            <lower>-0.01</lower>
            <upper>0.01</upper>
            <effort>0</effort>
            <velocity>0</velocity>
          </limit>
          <dynamics>
            <spring_reference>0</spring_reference>
            <spring_stiffness>1500</spring_stiffness>
            <damping>100</damping>
          </dynamics>
        </axis>
      </joint>
      <joint name='blslower2upper' type='prismatic'>
        <child>blsupper</child>
        <parent>blslower</parent>
        <axis>
          <xyz expressed_in='__model__'>-0.804128 0.131224 -0.579792</xyz>
          <limit>
            <lower>-0.01</lower>
            <upper>0.01</upper>
            <effort>0</effort>
            <velocity>0</velocity>
          </limit>
          <dynamics>
            <spring_reference>0</spring_reference>
            <spring_stiffness>1500</spring_stiffness>
            <damping>100</damping>
          </dynamics>
        </axis>
      </joint>
      <joint name='frslower2upper' type='prismatic'>
        <child>frsupper</child>
        <parent>frslower</parent>
        <axis>
          <xyz expressed_in='__model__'>0.804115 -0.131221 -0.57981</xyz>
          <limit>
            <lower>-0.01</lower>
            <upper>0.01</upper>
            <effort>0</effort>
            <velocity>0</velocity>
          </limit>
          <dynamics>
            <spring_reference>0</spring_reference>
            <spring_stiffness>1500</spring_stiffness>
            <damping>100</damping>
          </dynamics>
        </axis>
      </joint>
      <joint name='flslower2upper' type='prismatic'>
        <child>flsupper</child>
        <parent>flslower</parent>
        <axis>
          <xyz expressed_in='__model__'>0.804118 0.131227 -0.579804</xyz>
          <limit>
            <lower>-0.01</lower>
            <upper>0.01</upper>
            <effort>0</effort>
            <velocity>0</velocity>
          </limit>
          <dynamics>
            <spring_reference>0</spring_reference>
            <spring_stiffness>1500</spring_stiffness>
            <damping>100</damping>
          </dynamics>
        </axis>
      </joint>
      <joint name='bli2body' type='ball'>
        <child>body</child>
        <parent>bli</parent>
        <pose>-0.125 0.0445 0.014 0 -0 0</pose>
      </joint>
      <joint name='blo2body' type='ball'>
        <child>body</child>
        <parent>blo</parent>
        <pose>-0.101 0.0615 -0.024 0 -0 0</pose>
      </joint>
      <joint name='blsupper2body' type='ball'>
        <child>body</child>
        <parent>blsupper</parent>
        <pose>-0.1895 0.071 0.024 0 -0 0</pose>
      </joint>
      <joint name='bri2body' type='ball'>
        <child>body</child>
        <parent>bri</parent>
        <pose>-0.125 -0.0445 0.014 0 -0 0</pose>
      </joint>
      <joint name='brsupper2body' type='ball'>
        <child>body</child>
        <parent>brsupper</parent>
        <pose>-0.1895 -0.071 0.024 0 -0 0</pose>
      </joint>
      <joint name='fli2body' type='ball'>
        <child>body</child>
        <parent>fli</parent>
        <pose>0.125 0.0445 0.014 0 -0 0</pose>
      </joint>
      <joint name='flo2body' type='ball'>
        <child>body</child>
        <parent>flo</parent>
        <pose>0.101 0.0615 -0.024 0 -0 0</pose>
      </joint>
      <joint name='flsupper2body' type='ball'>
        <child>body</child>
        <parent>flsupper</parent>
        <pose>0.1895 0.071 0.024 0 -0 0</pose>
      </joint>
      <joint name='fri2body' type='ball'>
        <child>body</child>
        <parent>fri</parent>
        <pose>0.125 -0.0445 0.014 0 -0 0</pose>
      </joint>
      <joint name='frsupper2body' type='ball'>
        <child>body</child>
        <parent>frsupper</parent>
        <pose>0.1895 -0.071 0.024 0 -0 0</pose>
      </joint>
      <frame name='3d_lidar::__model__' attached_to='3d_lidar::link'>
        <pose relative_to='__model__'>0 0 0.5 0 -0 0</pose>
      </frame>
      <link name='3d_lidar::link'>
        <inertial>
          <pose>0 0 0 0 -0 0</pose>
          <mass>0.001</mass>
          <inertia>
            <ixx>4.15e-06</ixx>
            <ixy>0</ixy>
            <ixz>0</ixz>
            <iyy>2.407e-06</iyy>
            <iyz>0</iyz>
            <izz>2.407e-06</izz>
          </inertia>
        </inertial>
        <visual name='visual'>
          <geometry>
            <mesh>
              <uri>model://hokuyo/meshes/hokuyo.dae</uri>
            </mesh>
          </geometry>
        </visual>
        <sensor name='3d_lidar' type='ray'>
          <ray>
            <scan>
              <horizontal>
                <samples>500</samples>
                <resolution>1</resolution>
                <min_angle>-3.14159</min_angle>
                <max_angle>3.14159</max_angle>
              </horizontal>
              <vertical>
                <samples>16</samples>
                <min_angle>-0.261799</min_angle>
                <max_angle>0.261799</max_angle>
              </vertical>
            </scan>
            <range>
              <min>0.2</min>
              <max>30</max>
              <resolution>0.01</resolution>
            </range>
          </ray>
          <plugin name='3d_laser' filename='libgazebo_ros_velodyne_laser.so'>
            <robotNamespace/>
            <topicName>/velodyne_points</topicName>
            <frameName>laser_3d</frameName>
            <gaussianNoise>0.008</gaussianNoise>
          </plugin>
          <always_on>1</always_on>
          <update_rate>15</update_rate>
          <visualize>0</visualize>
        </sensor>
        <pose relative_to='3d_lidar::__model__'>0 0 0 0 -0 0</pose>
        <self_collide>0</self_collide>
        <enable_wind>0</enable_wind>
        <kinematic>0</kinematic>
      </link>
      <joint name='lidar_joint' type='fixed'>
        <child>body</child>
        <parent>3d_lidar::link</parent>
        <axis>
          <xyz>0 0 2</xyz>
          <limit>
            <upper>0</upper>
            <lower>0</lower>
          </limit>
        </axis>
      </joint>
      <frame name='imu_gazebo::__model__' attached_to='imu_gazebo::link'>
        <pose relative_to='__model__'>0 0 0.08 0 -0 0</pose>
      </frame>
      <link name='imu_gazebo::link'>
        <pose relative_to='imu_gazebo::__model__'>0 0 0 0 -0 0</pose>
        <inertial>
          <mass>0.001</mass>
          <inertia>
            <ixx>1.66667e-07</ixx>
            <iyy>1.66667e-07</iyy>
            <izz>1.66667e-07</izz>
            <ixy>0</ixy>
            <ixz>0</ixz>
            <iyz>0</iyz>
          </inertia>
          <pose>0 0 0 0 -0 0</pose>
        </inertial>
        <gravity>1</gravity>
        <sensor name='imu_sensor' type='imu'>
          <always_on>1</always_on>
          <update_rate>20</update_rate>
          <visualize>1</visualize>
          <topic>imu_gazebo</topic>
          <plugin name='imu_plugin' filename='libgazebo_ros_imu_sensor.so'>
            <topicName>imu_gazebo</topicName>
            <bodyName>imu_link</bodyName>
            <updateRateHZ>10</updateRateHZ>
            <gaussianNoise>0.0</gaussianNoise>
            <xyzOffset>0 0 0</xyzOffset>
            <rpyOffset>0 -0 0</rpyOffset>
            <frameName>imu_link</frameName>
            <initialOrientationAsReference>0</initialOrientationAsReference>
          </plugin>
          <pose>0 0 -0.3 0 -0 0</pose>
          <imu/>
          <parent>imu_gazebo::link</parent>
        </sensor>
        <self_collide>0</self_collide>
        <enable_wind>0</enable_wind>
        <kinematic>0</kinematic>
      </link>
      <joint name='imu_joint' type='fixed'>
        <child>body</child>
        <parent>imu_gazebo::link</parent>
        <axis>
          <xyz>0 0 1.9</xyz>
          <limit>
            <upper>0</upper>
            <lower>0</lower>
          </limit>
        </axis>
      </joint>
      <plugin name='cliffordPlugin' filename='libcliffordPlugin.so'>
        <robotNamespace>/</robotNamespace>
      </plugin>
      <pose>0 0 0.2 0 -0 0</pose>
    </model>
  </world>
</sdf>
